Workbook

Sheet BTC COINS
B1: Index | C1: BRRNY | D1: BRRNY | E1: BRRNY | F1: XBX | G1: BRRNY | H1: BRRNY | I1: Fidelity | J1: XBX | K1: MarketVector | L1: BRRNY
B2: ConId | C2: 677037663 | D2: 677037658 | E2: 677037676 | F2: 741192224 | G2: 676783288 | H2: 676783282 | I2: 676783301 | J2: 349966059 | K2: 677037670 | L2: 677037673
B3: Annual Fee | C3: 0.0021 | D3: 0.002 | E3: 0.0025 | F3: 0.0015 | G3: 0.0025 | H3: 0.0019 | I3: 0.0025 | J3: 0.015 | K3: 0 | L3: 0.0025
A4: 365 | B4: Daily Fee | C4: =C3/$A4 -> 5.7534247e-06 | D4: =D3/$A4 -> 5.4794521e-06 | E4: =E3/$A4 -> 6.8493151e-06 | F4: =F3/$A4 -> 4.109589e-06 | G4: =G3/$A4 -> 6.8493151e-06 | H4: =H3/$A4 -> 5.2054795e-06 | I4: =I3/$A4 -> 6.8493151e-06 | J4: =J3/$A4 -> 4.109589e-05 | ... L4: =L3/$A4 -> 6.8493151e-06
A6: DOW | B6: Date | C6: ARKB | D6: BITB | E6: BRRR | F6: BTC | G6: BTCW | H6: EZBC | I6: FBTC | J6: GBTC | K6: HODL | L6: IBIT | M6: Sum | N6: Change | O6: Pct Change | P6: Price | Q6: Price Change | R6: Price % Chg
A7: =scalars[[#This Row],[DOW]] -> Sunday | B7: 46082
A8: =scalars[[#This Row],[DOW]] -> Monday | B8: =B7+1 -> 46083
A9: =scalars[[#This Row],[DOW]] -> Tuesday | B9: =B8+1 -> 46084
A10: =scalars[[#This Row],[DOW]] -> Wednesday | B10: =B9+1 -> 46085
A11: =scalars[[#This Row],[DOW]] -> Thursday | B11: =B10+1 -> 46086
A12: =scalars[[#This Row],[DOW]] -> Friday | B12: =B11+1 -> 46087
A13: =scalars[[#This Row],[DOW]] -> Saturday | B13: =B12+1 -> 46088
A14: =scalars[[#This Row],[DOW]] -> Sunday | B14: =B13+1 -> 46089
A15: =scalars[[#This Row],[DOW]] -> Monday | B15: =B14+1 -> 46090
A16: =scalars[[#This Row],[DOW]] -> Tuesday | B16: =B15+1 -> 46091
A17: =scalars[[#This Row],[DOW]] -> Wednesday | B17: =B16+1 -> 46092
A18: =scalars[[#This Row],[DOW]] -> Thursday | B18: =B17+1 -> 46093
A19: =scalars[[#This Row],[DOW]] -> Friday | B19: =B18+1 -> 46094
... A21: =scalars[[#This Row],[DOW]] -> Sunday | B21: =B20+1 -> 46096
A22: =scalars[[#This Row],[DOW]] -> Monday | B22: =B21+1 -> 46097 | C22: =ARKB!G21 -> 35644.71 | D22: =BITB!H21 -> 38920.51 | E22: =BRRR!G22 -> 6256.69 | F22: =BTC!J21 -> 51689.489 | G22: =BTCW!H21 -> 2163 | H22: =H23 -> 6245.79 | J22: =GBTC!K21 -> 155874.24 | K22: =HODL!H21 -> 17153.107 | L22: =IBIT!G21 -> 784061.76 | M22: =SUM(btc_ratios3[[#This Row],[ARKB]:[IBIT]]) -> 1098009.3
A23: =scalars[[#This Row],[DOW]] -> Tuesday | B23: =B22+1 -> 46098 | C23: =ARKB!G22 -> 35677.89 | D23: =BITB!H22 -> 38920.51 | E23: =BRRR!G23 -> 6256.65 | F23: =BTC!J22 -> 51689.277 | G23: =G22 -> 2163 | H23: =EZBC!F22 -> 6245.79 | J23: =GBTC!K22 -> 155867.83 | K23: =HODL!H22 -> 17068.259 | L23: =IBIT!G22 -> 786329.17 | M23: =SUM(btc_ratios3[[#This Row],[ARKB]:[IBIT]]) -> 1100218.4 | N23: =btc_ratios3[[#This Row],[Sum]]-M22 -> 2209.0784 | O23: =btc_ratios3[[#This Row],[Sum]]/M22-1 -> 0.0020118941 | P23: =ARKB!H22 -> 74681.96
A24: =scalars[[#This Row],[DOW]] -> Wednesday | B24: =B23+1 -> 46099 | C24: =ARKB!G23 -> 35677.89 | D24: =BITB!H23 -> 38822.75 | E24: =BRRR!G24 -> 6301.75 | F24: =BTC!J23 -> 51689.064 | G24: =G23 -> 2163 | H24: =EZBC!F23 -> 6243.76 | J24: =GBTC!K23 -> 155861.43 | K24: =HODL!H23 -> 17110.684 | L24: =IBIT!G23 -> 785853.01 | M24: =SUM(btc_ratios3[[#This Row],[ARKB]:[IBIT]]) -> 1099723.3 | N24: =btc_ratios3[[#This Row],[Sum]]-M23 -> -495.0408 | O24: =btc_ratios3[[#This Row],[Sum]]/M23-1 -> -0.00044994776 | P24: =ARKB!H23 -> 71208.94 | Q24: =btc_ratios3[[#This Row],[Price]]-P23 -> -3473.02 | R24: =btc_ratios3[[#This Row],[Price]]/P23-1 -> -0.046504136
A25: =scalars[[#This Row],[DOW]] -> Thursday | B25: =B24+1 -> 46100 | C25: =ARKB!G24 -> 35462.18 | D25: =BITB!H24 -> 38578.33 | E25: =BRRR!G25 -> 6301.7 | F25: =BTC!J24 -> 51688.852 | G25: =G24 -> 2163 | H25: =AVERAGE(H24,H26) -> 6273.295 | J25: =GBTC!K24 -> 155590.2 | K25: =HODL!H24 -> 17110.681 | L25: =IBIT!G24 -> 785308.85 | M25: =SUM(btc_ratios3[[#This Row],[ARKB]:[IBIT]]) -> 1098477.1 | N25: =btc_ratios3[[#This Row],[Sum]]-M24 -> -1246.2525 | O25: =btc_ratios3[[#This Row],[Sum]]/M24-1 -> -0.0011332418 | P25: =ARKB!H24 -> 70292.52 | Q25: =btc_ratios3[[#This Row],[Price]]-P24 -> -916.42 | R25: =btc_ratios3[[#This Row],[Price]]/P24-1 -> -0.012869452
A26: =scalars[[#This Row],[DOW]] -> Friday | B26: =B25+1 -> 46101 | C26: =ARKB!G25 -> 35462.18 | D26: =BITB!H25 -> 38578.33 | E26: =BRRR!G29 -> 6301.49 | F26: =BTC!J25 -> 51754.998 | G26: =G25 -> 2163 | H26: =EZBC!F25 -> 6302.83 | J26: =GBTC!K25 -> 155505.92 | K26: =HODL!H25 -> 17110.681 | L26: =IBIT!G25 -> 784651.3 | M26: =SUM(btc_ratios3[[#This Row],[ARKB]:[IBIT]]) -> 1097830.7 | N26: =btc_ratios3[[#This Row],[Sum]]-M25 -> -646.3546 | O26: =btc_ratios3[[#This Row],[Sum]]/M25-1 -> -0.00058840973 | P26: =ARKB!H25 -> 69873.12 | Q26: =btc_ratios3[[#This Row],[Price]]-P25 -> -419.4 | R26: =btc_ratios3[[#This Row],[Price]]/P25-1 -> -0.0059664954
A27: =scalars[[#This Row],[DOW]] -> Saturday | B27: =B26+1 -> 46102
A28: =scalars[[#This Row],[DOW]] -> Sunday | B28: =B27+1 -> 46103
A29: =scalars[[#This Row],[DOW]] -> Monday | B29: =B28+1 -> 46104
A30: =scalars[[#This Row],[DOW]] -> Tuesday | B30: =B29+1 -> 46105 | C30: =ARKB!G29 -> 35329.43 | D30: =BITB!H29 -> 38339.35 | E30: =BRRR!G30 -> 6301.44 | F30: =BTC!J29 -> 51754.147 | G30: =G26 -> 2163 | H30: =EZBC!F29 -> 6302.83 | J30: =GBTC!K29 -> 155114.36 | K30: =HODL!H29 -> 17153.102 | L30: =IBIT!G29 -> 786850.58 | M30: =SUM(btc_ratios3[[#This Row],[ARKB]:[IBIT]]) -> 1099308.2 | N30: =btc_ratios3[[#This Row],[Sum]]-M26 -> 1477.5087 | O30: =btc_ratios3[[#This Row],[Sum]]/M26-1 -> 0.0013458438 | P30: =ARKB!H29 -> 69451.67 | Q30: =btc_ratios3[[#This Row],[Price]]-P26 -> -421.45 | R30: =btc_ratios3[[#This Row],[Price]]/P26-1 -> -0.0060316471
A31: =scalars[[#This Row],[DOW]] -> Wednesday | B31: =B30+1 -> 46106 | C31: =ARKB!G30 -> 35261.4 | D31: =BITB!H30 -> 38339.35 | E31: =BRRR!G31 -> 6301.4 | F31: =BTC!J30 -> 51753.934 | G31: =G30 -> 2163 | H31: =EZBC!F30 -> 6302.83 | J31: =GBTC!K30 -> 155107.98 | K31: =HODL!H30 -> 17039.977 | L31: =IBIT!G30 -> 785852.96 | M31: =SUM(btc_ratios3[[#This Row],[ARKB]:[IBIT]]) -> 1098122.8 | N31: =btc_ratios3[[#This Row],[Sum]]-M30 -> -1185.4044 | O31: =btc_ratios3[[#This Row],[Sum]]/M30-1 -> -0.0010783185 | P31: =ARKB!H30 -> 70883.73 | Q31: =btc_ratios3[[#This Row],[Price]]-P30 -> 1432.06 | R31: =btc_ratios3[[#This Row],[Price]]/P30-1 -> 0.020619519
A32: =scalars[[#This Row],[DOW]] -> Thursday | B32: =B31+1 -> 46107 | C32: =ARKB!G31 -> 34816.72 | D32: =BITB!H31 -> 37855.97 | E32: =BRRR!G32 -> 6301.4 | F32: =BTC!J31 -> 51753.722 | G32: =BTCW!H31 -> 2163 | H32: =EZBC!F31 -> 6302.83 | J32: =GBTC!K31 -> 155101.61 | K32: =HODL!H31 -> 17039.975 | L32: =IBIT!G31 -> 785240.8 | M32: =SUM(btc_ratios3[[#This Row],[ARKB]:[IBIT]]) -> 1096576 | N32: =btc_ratios3[[#This Row],[Sum]]-M31 -> -1546.8033 | O32: =btc_ratios3[[#This Row],[Sum]]/M31-1 -> -0.0014085886 | P32: =ARKB!H31 -> 68478.86 | Q32: =btc_ratios3[[#This Row],[Price]]-P31 -> -2404.87 | R32: =btc_ratios3[[#This Row],[Price]]/P31-1 -> -0.033926967
A33: =scalars[[#This Row],[DOW]] -> Friday | B33: =B32+1 -> 46108 | C33: =AVERAGE(C32,C36) -> 35023.355 | D33: =BITB!H32 -> 37573.55 | E33: =BRRR!G35 -> 6301.23 | F33: =BTC!J32 -> 51673.881 | G33: =G32 -> 2163 | H33: =H32 -> 6302.83 | J33: =GBTC!K32 -> 154729.28 | K33: =HODL!H32 -> 17004.62 | L33: =IBIT!G32 -> 782180.06 | M33: =SUM(btc_ratios3[[#This Row],[ARKB]:[IBIT]]) -> 1092951.8 | N33: =btc_ratios3[[#This Row],[Sum]]-M32 -> -3624.2225 | O33: =btc_ratios3[[#This Row],[Sum]]/M32-1 -> -0.0033050353 | P33: =BITB!J32 -> 65842.59 | Q33: =btc_ratios3[[#This Row],[Price]]-P32 -> -2636.27 | R33: =btc_ratios3[[#This Row],[Price]]/P32-1 -> -0.038497574
A34: =scalars[[#This Row],[DOW]] -> Saturday | B34: =B33+1 -> 46109
A35: =scalars[[#This Row],[DOW]] -> Sunday | B35: =B34+1 -> 46110
A36: =scalars[[#This Row],[DOW]] -> Monday | B36: =B35+1 -> 46111 | C36: =ARKB!G35 -> 35229.99 | D36: =BITB!H35 -> 37573.55 | E36: =BRRR!G36 -> 6301.18 | F36: =BTC!J35 -> 51673.244 | G36: =BTCW!H35 -> 2163 | H36: =EZBC!F35 -> 6302.83 | J36: =GBTC!K35 -> 154710.21 | K36: =HODL!H35 -> 17004.624 | L36: =IBIT!G35 -> 782293.42 | M36: =SUM(btc_ratios3[[#This Row],[ARKB]:[IBIT]]) -> 1093252 | N36: =btc_ratios3[[#This Row],[Sum]]-M33 -> 300.2346 | O36: =btc_ratios3[[#This Row],[Sum]]/M33-1 -> 0.00027470068 | P36: =ARKB!H35 -> 66355.48 | Q36: =btc_ratios3[[#This Row],[Price]]-P33 -> 512.89 | R36: =btc_ratios3[[#This Row],[Price]]/P33-1 -> 0.0077896389
A37: =scalars[[#This Row],[DOW]] -> Tuesday | B37: =B36+1 -> 46112 | C37: =ARKB!G36 -> 35246.58 | D37: =BITB!H36 -> 37593.96 | E37: =BRRR!G37 -> 6301.14 | F37: =BTC!J36 -> 51673.032 | G37: =G36 -> 2163 | H37: =EZBC!F36 -> 6302.83 | J37: =GBTC!K36 -> 154703.85 | K37: =HODL!H36 -> 17004.624 | L37: =IBIT!G36 -> 783744.4 | M37: =SUM(btc_ratios3[[#This Row],[ARKB]:[IBIT]]) -> 1094733.4 | N37: =btc_ratios3[[#This Row],[Sum]]-M36 -> 1481.371 | O37: =btc_ratios3[[#This Row],[Sum]]/M36-1 -> 0.0013550132 | P37: =ARKB!H36 -> 67831.76 | Q37: =btc_ratios3[[#This Row],[Price]]-P36 -> 1476.28 | R37: =btc_ratios3[[#This Row],[Price]]/P36-1 -> 0.022248049
A38: =scalars[[#This Row],[DOW]] -> Wednesday | B38: =B37+1 -> 46113 | C38: =ARKB!G37 -> 35246.58 | D38: =BITB!H37 -> 37512.49 | E38: =BRRR!G38 -> 6300.97 | F38: =BTC!J37 -> 51672.819 | G38: =BTCW!H37 -> 2163 | H38: =EZBC!F37 -> 6302.83 | J38: =GBTC!K37 -> 154697.49 | K38: =HODL!H37 -> 17004.625 | L38: =IBIT!G37 -> 782474.77 | M38: =SUM(btc_ratios3[[#This Row],[ARKB]:[IBIT]]) -> 1093375.6 | N38: =btc_ratios3[[#This Row],[Sum]]-M37 -> -1357.8376 | O38: =btc_ratios3[[#This Row],[Sum]]/M37-1 -> -0.0012403363 | P38: =ARKB!H37 -> 68149.22 | Q38: =btc_ratios3[[#This Row],[Price]]-P37 -> 317.46 | R38: =btc_ratios3[[#This Row],[Price]]/P37-1 -> 0.0046801086
A39: =scalars[[#This Row],[DOW]] -> Thursday | B39: =B38+1 -> 46114 | C39: =ARKB!G38 -> 35246.58 | D39: =BITB!H38 -> 37512.49 | E39: =BRRR!G42 -> 6334.78 | F39: =BTC!J38 -> 51823.011 | G39: =BTCW!H38 -> 2163 | H39: =EZBC!F38 -> 6302.83 | J39: =GBTC!K38 -> 154496.52 | K39: =HODL!H38 -> 17004.624 | L39: =IBIT!G38 -> 782429.4 | M39: =SUM(btc_ratios3[[#This Row],[ARKB]:[IBIT]]) -> 1093313.2 | N39: =btc_ratios3[[#This Row],[Sum]]-M38 -> -62.3381 | O39: =btc_ratios3[[#This Row],[Sum]]/M38-1 -> -5.7014352e-05 | P39: =ARKB!H38 -> 66994.87 | Q39: =btc_ratios3[[#This Row],[Price]]-P38 -> -1154.35 | R39: =btc_ratios3[[#This Row],[Price]]/P38-1 -> -0.016938565
A40: =scalars[[#This Row],[DOW]] -> Friday | B40: =B39+1 -> 46115 | M40: HOLIDAY
A41: =scalars[[#This Row],[DOW]] -> Saturday | B41: =B40+1 -> 46116 | Q41: =btc_ratios3[[#This Row],[Price]]-P40 -> 0
A42: =scalars[[#This Row],[DOW]] -> Sunday | B42: =B41+1 -> 46117
...

Sheet SCALARS
B1: Index | C1: BRRNY | D1: BRRNY | E1: BRRNY | F1: XBX | G1: BRRNY | H1: BRRNY | I1: Fidelity | J1: XBX | K1: MarketVector | L1: BRRNY | N1: BTCO — Invesco Galaxy Bitcoin ETF
B2: ConId | C2: 677037663 | D2: 677037658 | E2: 677037676 | F2: 741192224 | G2: 676783288 | H2: 676783282 | I2: 676783301 | J2: 349966059 | K2: 677037670 | L2: 677037673 | N2: MSBT - Morgan Stanley
B3: Annual Fee | C3: 0.0021 | D3: 0.002 | E3: 0.0025 | F3: 0.0015 | G3: 0.0025 | H3: 0.0019 | I3: 0.0025 | J3: 0.015 | K3: 0 | L3: 0.0025 | N3: Bitcoin ETF Fees Comparison - MooLoo
A4: 365 | B4: Daily Fee | C4: =C3/$A4 -> 5.7534247e-06 | D4: =D3/$A4 -> 5.4794521e-06 | E4: =E3/$A4 -> 6.8493151e-06 | F4: =F3/$A4 -> 4.109589e-06 | G4: =G3/$A4 -> 6.8493151e-06 | H4: =H3/$A4 -> 5.2054795e-06 | I4: =I3/$A4 -> 6.8493151e-06 | J4: =J3/$A4 -> 4.109589e-05 | ... L4: =L3/$A4 -> 6.8493151e-06
B5: Market Bias | C5: 0 | D5: 0 | E5: 0 | F5: 0 | G5: 0 | H5: 0 | I5: 0 | J5: 0 | K5: 0 | L5: 0
A6: DOW | B6: Date | C6: ARKB | D6: BITB | E6: BRRR | F6: BTC | G6: BTCW | H6: EZBC | I6: FBTC | J6: GBTC | K6: HODL | L6: IBIT | N6: Number | O6: Day
A7: Sunday | B7: 46082 | C7: =3012.9766+C5 -> 3012.9766 | D7: =1840.9691+D5 -> 1840.9691 | E7: =3543.8163+E5 -> 3543.8163 | F7: =2260.2814+F5 -> 2260.2814 | G7: =945.3954+G5 -> 945.3954 | H7: =1729.0918+H5 -> 1729.0918 | I7: =1147.9526+I5 -> 1147.9526 | J7: =1282.9366+J5 -> 1282.9366 | K7: =3535.8029+K5 -> 3535.8029 | L7: =1763.6799+L5 -> 1763.6799 | N7: 1 | O7: Sunday
A8: =VLOOKUP(WEEKDAY(B8),$N$7:$O$13,2) -> Monday | B8: =B7+1 -> 46083 | C8: =ROUND(C7*(1+C$4),4) -> 3012.9939 | D8: =ROUND(D7*(1+D$4),4) -> 1840.9792 | E8: =ROUND(E7*(1+E$4),4) -> 3543.8406 | F8: =ROUND(F7*(1+F$4),4) -> 2260.2907 | G8: =ROUND(G7*(1+G$4),4) -> 945.4019 | H8: =ROUND(H7*(1+H$4),4) -> 1729.1008 | I8: =ROUND(I7*(1+I$4),4) -> 1147.9605 | J8: =ROUND(J7*(1+J$4),4) -> 1282.9893 | ... L8: =ROUND(L7*(1+L$4),4) -> 1763.692 | N8: 2 | O8: Monday
A9: =VLOOKUP(WEEKDAY(B9),$N$7:$O$13,2) -> Tuesday | B9: =B8+1 -> 46084 | C9: =ROUND(C8*(1+C$4),4) -> 3013.0112 | D9: =ROUND(D8*(1+D$4),4) -> 1840.9893 | E9: =ROUND(E8*(1+E$4),4) -> 3543.8649 | F9: =ROUND(F8*(1+F$4),4) -> 2260.3 | G9: =ROUND(G8*(1+G$4),4) -> 945.4084 | H9: =ROUND(H8*(1+H$4),4) -> 1729.1098 | I9: =ROUND(I8*(1+I$4),4) -> 1147.9684 | J9: =ROUND(J8*(1+J$4),4) -> 1283.042 | ... L9: =ROUND(L8*(1+L$4),4) -> 1763.7041 | N9: 3 | O9: Tuesday
A10: =VLOOKUP(WEEKDAY(B10),$N$7:$O$13,2) -> Wednesday | B10: =B9+1 -> 46085 | C10: =ROUND(C9*(1+C$4),4) -> 3013.0285 | D10: =ROUND(D9*(1+D$4),4) -> 1840.9994 | E10: =ROUND(E9*(1+E$4),4) -> 3543.8892 | F10: =ROUND(F9*(1+F$4),4) -> 2260.3093 | G10: =ROUND(G9*(1+G$4),4) -> 945.4149 | H10: =ROUND(H9*(1+H$4),4) -> 1729.1188 | I10: =ROUND(I9*(1+I$4),4) -> 1147.9763 | J10: =ROUND(J9*(1+J$4),4) -> 1283.0947 | ... L10: =ROUND(L9*(1+L$4),4) -> 1763.7162 | N10: 4 | O10: Wednesday
A11: =VLOOKUP(WEEKDAY(B11),$N$7:$O$13,2) -> Thursday | B11: =B10+1 -> 46086 | C11: =ROUND(C10*(1+C$4),4) -> 3013.0458 | D11: =ROUND(D10*(1+D$4),4) -> 1841.0095 | E11: =ROUND(E10*(1+E$4),4) -> 3543.9135 | F11: =ROUND(F10*(1+F$4),4) -> 2260.3186 | G11: =ROUND(G10*(1+G$4),4) -> 945.4214 | H11: =ROUND(H10*(1+H$4),4) -> 1729.1278 | I11: =ROUND(I10*(1+I$4),4) -> 1147.9842 | J11: =ROUND(J10*(1+J$4),4) -> 1283.1474 | ... L11: =ROUND(L10*(1+L$4),4) -> 1763.7283 | N11: 5 | O11: Thursday
A12: =VLOOKUP(WEEKDAY(B12),$N$7:$O$13,2) -> Friday | B12: =B11+1 -> 46087 | C12: =ROUND(C11*(1+C$4),4) -> 3013.0631 | D12: =ROUND(D11*(1+D$4),4) -> 1841.0196 | E12: =ROUND(E11*(1+E$4),4) -> 3543.9378 | F12: =ROUND(F11*(1+F$4),4) -> 2260.3279 | G12: =ROUND(G11*(1+G$4),4) -> 945.4279 | H12: =ROUND(H11*(1+H$4),4) -> 1729.1368 | I12: =ROUND(I11*(1+I$4),4) -> 1147.9921 | J12: =ROUND(J11*(1+J$4),4) -> 1283.2001 | ... L12: =ROUND(L11*(1+L$4),4) -> 1763.7404 | N12: 6 | O12: Friday
A13: =VLOOKUP(WEEKDAY(B13),$N$7:$O$13,2) -> Saturday | B13: =B12+1 -> 46088 | C13: =ROUND(C12*(1+C$4),4) -> 3013.0804 | D13: =ROUND(D12*(1+D$4),4) -> 1841.0297 | E13: =ROUND(E12*(1+E$4),4) -> 3543.9621 | F13: =ROUND(F12*(1+F$4),4) -> 2260.3372 | G13: =ROUND(G12*(1+G$4),4) -> 945.4344 | H13: =ROUND(H12*(1+H$4),4) -> 1729.1458 | I13: =ROUND(I12*(1+I$4),4) -> 1148 | J13: =ROUND(J12*(1+J$4),4) -> 1283.2528 | ... L13: =ROUND(L12*(1+L$4),4) -> 1763.7525 | N13: 7 | O13: Saturday
A14: =VLOOKUP(WEEKDAY(B14),$N$7:$O$13,2) -> Sunday | B14: =B13+1 -> 46089 | C14: =ROUND(C13*(1+C$4),4) -> 3013.0977 | D14: =ROUND(D13*(1+D$4),4) -> 1841.0398 | E14: =ROUND(E13*(1+E$4),4) -> 3543.9864 | F14: =ROUND(F13*(1+F$4),4) -> 2260.3465 | G14: =ROUND(G13*(1+G$4),4) -> 945.4409 | H14: =ROUND(H13*(1+H$4),4) -> 1729.1548 | I14: =ROUND(I13*(1+I$4),4) -> 1148.0079 | J14: =ROUND(J13*(1+J$4),4) -> 1283.3055 | ... L14: =ROUND(L13*(1+L$4),4) -> 1763.7646
A15: =VLOOKUP(WEEKDAY(B15),$N$7:$O$13,2) -> Monday | B15: =B14+1 -> 46090 | C15: =ROUND(C14*(1+C$4),4) -> 3013.115 | D15: =ROUND(D14*(1+D$4),4) -> 1841.0499 | E15: =ROUND(E14*(1+E$4),4) -> 3544.0107 | F15: =ROUND(F14*(1+F$4),4) -> 2260.3558 | G15: =ROUND(G14*(1+G$4),4) -> 945.4474 | H15: =ROUND(H14*(1+H$4),4) -> 1729.1638 | I15: =ROUND(I14*(1+I$4),4) -> 1148.0158 | J15: =ROUND(J14*(1+J$4),4) -> 1283.3582 | ... L15: =ROUND(L14*(1+L$4),4) -> 1763.7767
A16: =VLOOKUP(WEEKDAY(B16),$N$7:$O$13,2) -> Tuesday | B16: =B15+1 -> 46091 | C16: =ROUND(C15*(1+C$4),4) -> 3013.1323 | D16: =ROUND(D15*(1+D$4),4) -> 1841.06 | E16: =ROUND(E15*(1+E$4),4) -> 3544.035 | F16: =ROUND(F15*(1+F$4),4) -> 2260.3651 | G16: =ROUND(G15*(1+G$4),4) -> 945.4539 | H16: =ROUND(H15*(1+H$4),4) -> 1729.1728 | I16: =ROUND(I15*(1+I$4),4) -> 1148.0237 | J16: =ROUND(J15*(1+J$4),4) -> 1283.4109 | ... L16: =ROUND(L15*(1+L$4),4) -> 1763.7888
A17: =VLOOKUP(WEEKDAY(B17),$N$7:$O$13,2) -> Wednesday | B17: =B16+1 -> 46092 | C17: =ROUND(C16*(1+C$4),4) -> 3013.1496 | D17: =ROUND(D16*(1+D$4),4) -> 1841.0701 | E17: =ROUND(E16*(1+E$4),4) -> 3544.0593 | F17: =ROUND(F16*(1+F$4),4) -> 2260.3744 | G17: =ROUND(G16*(1+G$4),4) -> 945.4604 | H17: =ROUND(H16*(1+H$4),4) -> 1729.1818 | I17: =ROUND(I16*(1+I$4),4) -> 1148.0316 | J17: =ROUND(J16*(1+J$4),4) -> 1283.4636 | ... L17: =ROUND(L16*(1+L$4),4) -> 1763.8009
A18: =VLOOKUP(WEEKDAY(B18),$N$7:$O$13,2) -> Thursday | B18: =B17+1 -> 46093 | C18: =ROUND(C17*(1+C$4),4) -> 3013.1669 | D18: =ROUND(D17*(1+D$4),4) -> 1841.0802 | E18: =ROUND(E17*(1+E$4),4) -> 3544.0836 | F18: =ROUND(F17*(1+F$4),4) -> 2260.3837 | G18: =ROUND(G17*(1+G$4),4) -> 945.4669 | H18: =ROUND(H17*(1+H$4),4) -> 1729.1908 | I18: =ROUND(I17*(1+I$4),4) -> 1148.0395 | J18: =ROUND(J17*(1+J$4),4) -> 1283.5163 | ... L18: =ROUND(L17*(1+L$4),4) -> 1763.813
A19: =VLOOKUP(WEEKDAY(B19),$N$7:$O$13,2) -> Friday | B19: =B18+1 -> 46094 | C19: =ROUND(C18*(1+C$4),4) -> 3013.1842 | D19: =ROUND(D18*(1+D$4),4) -> 1841.0903 | E19: =ROUND(E18*(1+E$4),4) -> 3544.1079 | F19: =ROUND(F18*(1+F$4),4) -> 2260.393 | G19: =ROUND(G18*(1+G$4),4) -> 945.4734 | H19: =ROUND(H18*(1+H$4),4) -> 1729.1998 | I19: =ROUND(I18*(1+I$4),4) -> 1148.0474 | J19: =ROUND(J18*(1+J$4),4) -> 1283.569 | ... L19: =ROUND(L18*(1+L$4),4) -> 1763.8251
A20: =VLOOKUP(WEEKDAY(B20),$N$7:$O$13,2) -> Saturday | B20: =B19+1 -> 46095 | C20: =ROUND(C19*(1+C$4),4) -> 3013.2015 | D20: =ROUND(D19*(1+D$4),4) -> 1841.1004 | E20: =ROUND(E19*(1+E$4),4) -> 3544.1322 | F20: =ROUND(F19*(1+F$4),4) -> 2260.4023 | G20: =ROUND(G19*(1+G$4),4) -> 945.4799 | H20: =ROUND(H19*(1+H$4),4) -> 1729.2088 | I20: =ROUND(I19*(1+I$4),4) -> 1148.0553 | J20: =ROUND(J19*(1+J$4),4) -> 1283.6217 | ... L20: =ROUND(L19*(1+L$4),4) -> 1763.8372
A21: =VLOOKUP(WEEKDAY(B21),$N$7:$O$13,2) -> Sunday | B21: =B20+1 -> 46096 | C21: =ROUND(C20*(1+C$4),4) -> 3013.2188 | D21: =ROUND(D20*(1+D$4),4) -> 1841.1105 | E21: =ROUND(E20*(1+E$4),4) -> 3544.1565 | F21: =ROUND(F20*(1+F$4),4) -> 2260.4116 | G21: =ROUND(G20*(1+G$4),4) -> 945.4864 | H21: =ROUND(H20*(1+H$4),4) -> 1729.2178 | I21: =ROUND(I20*(1+I$4),4) -> 1148.0632 | J21: =ROUND(J20*(1+J$4),4) -> 1283.6745 | ... L21: =ROUND(L20*(1+L$4),4) -> 1763.8493
A22: =VLOOKUP(WEEKDAY(B22),$N$7:$O$13,2) -> Monday | B22: =B21+1 -> 46097 | C22: =ROUND(C21*(1+C$4),4) -> 3013.2361 | D22: =ROUND(D21*(1+D$4),4) -> 1841.1206 | E22: =ROUND(E21*(1+E$4),4) -> 3544.1808 | F22: =ROUND(F21*(1+F$4),4) -> 2260.4209 | G22: =ROUND(G21*(1+G$4),4) -> 945.4929 | H22: =ROUND(H21*(1+H$4),4) -> 1729.2268 | I22: =ROUND(I21*(1+I$4),4) -> 1148.0711 | J22: =ROUND(J21*(1+J$4),4) -> 1283.7273 | ... L22: =ROUND(L21*(1+L$4),4) -> 1763.8614
A23: =VLOOKUP(WEEKDAY(B23),$N$7:$O$13,2) -> Tuesday | B23: =B22+1 -> 46098 | C23: =ROUND(C22*(1+C$4),4) -> 3013.2534 | D23: =ROUND(D22*(1+D$4),4) -> 1841.1307 | E23: =ROUND(E22*(1+E$4),4) -> 3544.2051 | F23: =ROUND(F22*(1+F$4),4) -> 2260.4302 | G23: =ROUND(G22*(1+G$4),4) -> 945.4994 | H23: =ROUND(H22*(1+H$4),4) -> 1729.2358 | I23: =ROUND(I22*(1+I$4),4) -> 1148.079 | J23: =ROUND(J22*(1+J$4),4) -> 1283.7801 | ... L23: =ROUND(L22*(1+L$4),4) -> 1763.8735
A24: =VLOOKUP(WEEKDAY(B24),$N$7:$O$13,2) -> Wednesday | B24: =B23+1 -> 46099 | C24: =ROUND(C23*(1+C$4),4) -> 3013.2707 | D24: =ROUND(D23*(1+D$4),4) -> 1841.1408 | E24: =ROUND(E23*(1+E$4),4) -> 3544.2294 | F24: =ROUND(F23*(1+F$4),4) -> 2260.4395 | G24: =ROUND(G23*(1+G$4),4) -> 945.5059 | H24: =ROUND(H23*(1+H$4),4) -> 1729.2448 | I24: =ROUND(I23*(1+I$4),4) -> 1148.0869 | J24: =ROUND(J23*(1+J$4),4) -> 1283.8329 | ... L24: =ROUND(L23*(1+L$4),4) -> 1763.8856
A25: =VLOOKUP(WEEKDAY(B25),$N$7:$O$13,2) -> Thursday | B25: =B24+1 -> 46100 | C25: =ROUND(C24*(1+C$4),4) -> 3013.288 | D25: =ROUND(D24*(1+D$4),4) -> 1841.1509 | E25: =ROUND(E24*(1+E$4),4) -> 3544.2537 | F25: =ROUND(F24*(1+F$4),4) -> 2260.4488 | G25: =ROUND(G24*(1+G$4),4) -> 945.5124 | H25: =ROUND(H24*(1+H$4),4) -> 1729.2538 | I25: =ROUND(I24*(1+I$4),4) -> 1148.0948 | J25: =ROUND(J24*(1+J$4),4) -> 1283.8857 | ... L25: =ROUND(L24*(1+L$4),4) -> 1763.8977
... A371: =VLOOKUP(WEEKDAY(B371),$N$7:$O$13,2) -> Sunday | B371: =B370+1 -> 46446 | C371: =ROUND(C370*(1+C$4),4) -> 3019.295 | D371: =ROUND(D370*(1+D$4),4) -> 1844.6455 | E371: =ROUND(E370*(1+E$4),4) -> 3552.6615 | F371: =ROUND(F370*(1+F$4),4) -> 2263.6666 | G371: =ROUND(G370*(1+G$4),4) -> 947.7614 | H371: =ROUND(H370*(1+H$4),4) -> 1732.3678 | I371: =ROUND(I370*(1+I$4),4) -> 1150.8282 | J371: =ROUND(J370*(1+J$4),4) -> 1302.2717 | ... L371: =ROUND(L370*(1+L$4),4) -> 1768.0843

Sheet BITO and EETH
A1: https://www.proshares.com/our-etfs/strategic/bito
A2: https://www.proshares.com/our-etfs/strategic/eeth
C4: BTC | J4: ETH
A5: DOW | B5: Date | C5: CME 1ST | D5: CME 2ND | E5: CME TOTAL | F5: CB 1ST | G5: CB 2ND | H5: CB TOTAL | J5: CME 1ST | K5: CME 2ND | L5: CME TOTAL
A6: =SCALARS!A7 -> Sunday | B6: =SCALARS!B7 -> 46082
A7: =SCALARS!A8 -> Monday | B7: =SCALARS!B8 -> 46083
A8: =SCALARS!A9 -> Tuesday | B8: =SCALARS!B9 -> 46084
A9: =SCALARS!A10 -> Wednesday | B9: =SCALARS!B10 -> 46085
A10: =SCALARS!A11 -> Thursday | B10: =SCALARS!B11 -> 46086
A11: =SCALARS!A12 -> Friday | B11: =SCALARS!B12 -> 46087
A12: =SCALARS!A13 -> Saturday | B12: =SCALARS!B13 -> 46088
A13: =SCALARS!A14 -> Sunday | B13: =SCALARS!B14 -> 46089
A14: =SCALARS!A15 -> Monday | B14: =SCALARS!B15 -> 46090
A15: =SCALARS!A16 -> Tuesday | B15: =SCALARS!B16 -> 46091
A16: =SCALARS!A17 -> Wednesday | B16: =SCALARS!B17 -> 46092
A17: =SCALARS!A18 -> Thursday | B17: =SCALARS!B18 -> 46093
... A85: =SCALARS!A86 -> Tuesday | B85: =SCALARS!B86 -> 46161
A86: =SCALARS!A87 -> Wednesday | B86: =SCALARS!B87 -> 46162 | C86: 4435 | E86: =SUM(C86:D86) -> 4435 | H86: =SUM(F86:G86) -> 0
A87: =SCALARS!A88 -> Thursday | B87: =SCALARS!B88 -> 46163 | C87: 3465 | D87: 970 | E87: =SUM(C87:D87) -> 4435 | H87: =SUM(F87:G87) -> 0 | N87: FIRST MOVE
A88: =SCALARS!A89 -> Friday | B88: =SCALARS!B89 -> 46164 | C88: 2425 | D88: 2010 | E88: =SUM(C88:D88) -> 4435 | H88: =SUM(F88:G88) -> 0 | J88: 374 | K88: 232 | L88: =SUM(J88:K88) -> 606
A89: =SCALARS!A90 -> Saturday | B89: =SCALARS!B90 -> 46165
A90: =SCALARS!A91 -> Sunday | B90: =SCALARS!B91 -> 46166
A91: =SCALARS!A92 -> Monday | B91: =SCALARS!B92 -> 46167 | C91: HOLIDAY
A92: =SCALARS!A93 -> Tuesday | B92: =SCALARS!B93 -> 46168 | C92: 3030 | D92: 1405 | E92: =SUM(C92:D92) -> 4435 | H92: =SUM(F92:G92) -> 0 | J92: 254 | K92: 352 | L92: =SUM(J92:K92) -> 606
A93: =SCALARS!A94 -> Wednesday | B93: =SCALARS!B94 -> 46169 | C93: 3870 | D93: 600 | E93: =SUM(C93:D93) -> 4470 | H93: =SUM(F93:G93) -> 0 | J93: 472 | K93: 134 | L93: =SUM(J93:K93) -> 606
A94: =SCALARS!A95 -> Thursday | B94: =SCALARS!B95 -> 46170 | D94: 4230 | E94: =SUM(C94:D94) -> 4230 | G94: 1000 | H94: =SUM(F94:G94) -> 1000 | K94: 605 | L94: =SUM(J94:K94) -> 605
A95: =SCALARS!A96 -> Friday | B95: =SCALARS!B96 -> 46171 | D95: 4220 | E95: =SUM(C95:D95) -> 4220 | G95: 1000 | H95: =SUM(F95:G95) -> 1000 | K95: 605 | L95: =SUM(J95:K95) -> 605 | N95: EXPIRATION DAY
A96: =SCALARS!A97 -> Saturday | B96: =SCALARS!B97 -> 46172
A97: =SCALARS!A98 -> Sunday | B97: =SCALARS!B98 -> 46173
A98: =SCALARS!A99 -> Monday | B98: =SCALARS!B99 -> 46174 | C98: 4220 | E98: =SUM(C98:D98) -> 4220 | F98: 1000 | H98: =SUM(F98:G98) -> 1000 | J98: 605 | L98: =SUM(J98:K98) -> 605
A99: =SCALARS!A100 -> Tuesday | B99: =SCALARS!B100 -> 46175 | C99: 4235 | E99: =SUM(C99:D99) -> 4235 | F99: 1000 | H99: =SUM(F99:G99) -> 1000 | J99: 605 | L99: =SUM(J99:K99) -> 605
A100: =SCALARS!A101 -> Wednesday | B100: =SCALARS!B101 -> 46176 | C100: 4305 | E100: =SUM(C100:D100) -> 4305 | F100: 1000 | H100: =SUM(F100:G100) -> 1000 | J100: 605 | L100: =SUM(J100:K100) -> 605
A101: =SCALARS!A102 -> Thursday | B101: =SCALARS!B102 -> 46177 | C101: 4305 | E101: =SUM(C101:D101) -> 4305 | F101: 1000 | H101: =SUM(F101:G101) -> 1000 | J101: 599 | L101: =SUM(J101:K101) -> 599
A102: =SCALARS!A103 -> Friday | B102: =SCALARS!B103 -> 46178 | C102: 4230 | E102: =SUM(C102:D102) -> 4230 | F102: 1000 | H102: =SUM(F102:G102) -> 1000 | J102: 624 | L102: =SUM(J102:K102) -> 624
A103: =SCALARS!A104 -> Saturday | B103: =SCALARS!B104 -> 46179 | E103: =SUM(C103:D103) -> 0 | H103: =SUM(F103:G103) -> 0 | L103: =SUM(J103:K103) -> 0
A104: =SCALARS!A105 -> Sunday | B104: =SCALARS!B105 -> 46180 | E104: =SUM(C104:D104) -> 0 | H104: =SUM(F104:G104) -> 0 | L104: =SUM(J104:K104) -> 0
A105: =SCALARS!A106 -> Monday | B105: =SCALARS!B106 -> 46181 | C105: 4230 | E105: =SUM(C105:D105) -> 4230 | F105: 1000 | H105: =SUM(F105:G105) -> 1000 | J105: 624 | L105: =SUM(J105:K105) -> 624
A106: =SCALARS!A107 -> Tuesday | B106: =SCALARS!B107 -> 46182 | C106: 4230 | E106: =SUM(C106:D106) -> 4230 | F106: 1000 | H106: =SUM(F106:G106) -> 1000 | J106: 624 | L106: =SUM(J106:K106) -> 624
A107: =SCALARS!A108 -> Wednesday | B107: =SCALARS!B108 -> 46183 | C107: 4215 | E107: =SUM(C107:D107) -> 4215 | F107: 1000 | H107: =SUM(F107:G107) -> 1000 | J107: 624 | L107: =SUM(J107:K107) -> 624
A108: =SCALARS!A109 -> Thursday | B108: =SCALARS!B109 -> 46184 | C108: 4130 | E108: =SUM(C108:D108) -> 4130 | F108: 1000 | H108: =SUM(F108:G108) -> 1000 | J108: 616 | L108: =SUM(J108:K108) -> 616
...

Sheet ARKB
A1: https://www.21shares.com/en-us/product/arkb
E4: WEEKLY PATTERN
A5: DOW | B5: Date | C5: TODAY'S RATIO | D5: SHS/ADJ BTC | E5: PREDICTED BIAS | F5: DIFF | G5: COIN ENTITLEMENT | H5: REF PRICE | I5: AUM | J5: SECUTITIES OUTSTANDING | K5: ADJ BTC | L5: SHS/BTC
A6: =SCALARS!A7 -> Sunday | B6: =SCALARS!B7 -> 46082 | C6: =SCALARS!C7 -> 3012.9766
A7: =SCALARS!A8 -> Monday | B7: =SCALARS!B8 -> 46083 | C7: =SCALARS!C8 -> 3012.9939
A8: =SCALARS!A9 -> Tuesday | B8: =SCALARS!B9 -> 46084 | C8: =SCALARS!C9 -> 3013.0112
A9: =SCALARS!A10 -> Wednesday | B9: =SCALARS!B10 -> 46085 | C9: =SCALARS!C10 -> 3013.0285
A10: =SCALARS!A11 -> Thursday | B10: =SCALARS!B11 -> 46086 | C10: =SCALARS!C11 -> 3013.0458
A11: =SCALARS!A12 -> Friday | B11: =SCALARS!B12 -> 46087 | C11: =SCALARS!C12 -> 3013.0631
A12: =SCALARS!A13 -> Saturday | B12: =SCALARS!B13 -> 46088 | C12: =SCALARS!C13 -> 3013.0804
A13: =SCALARS!A14 -> Sunday | B13: =SCALARS!B14 -> 46089 | C13: =SCALARS!C14 -> 3013.0977
A14: =SCALARS!A15 -> Monday | B14: =SCALARS!B15 -> 46090 | C14: =SCALARS!C15 -> 3013.115 | D14: =J14/K14 -> 3013.0963 | E14: =C14-C13 -> 0.0173 | F14: =C14-(D14+E14) -> 0.0013655606 | G14: 35566.78 | H14: 68865.77 | I14: 2.4482793e+09 | J14: 107120000 | K14: =I14/H14 -> 35551.469 | L14: =J14/G14 -> 3011.7992
A15: =SCALARS!A16 -> Tuesday | B15: =SCALARS!B16 -> 46091 | C15: =SCALARS!C16 -> 3013.1323 | D15: =J15/K15 -> 3013.1137 | E15: =C15-C14 -> 0.0173 | F15: =C15-(D15+E15) -> 0.0013298274 | G15: 35624.86 | H15: 70019.35 | I15: 2.4933431e+09 | J15: 107295000 | K15: =I15/H15 -> 35609.344 | L15: =J15/G15 -> 3011.8013
A16: =SCALARS!A17 -> Wednesday | B16: =SCALARS!B17 -> 46092 | C16: =SCALARS!C17 -> 3013.1496 | D16: =J16/K16 -> 3013.131 | E16: =C16-C15 -> 0.0173 | F16: =C16-(D16+E16) -> 0.0012940042 | G16: 35624.86 | H16: 70600.43 | I16: 2.5140205e+09 | J16: 107295000 | K16: =I16/H16 -> 35609.139 | L16: =J16/G16 -> 3011.8013
A17: =SCALARS!A18 -> Thursday | B17: =SCALARS!B18 -> 46093 | C17: =SCALARS!C18 -> 3013.1669 | D17: =J17/K17 -> 3013.183 | E17: =C17-C18 -> -0.0173 | F17: =C17-(D17+E17) -> 0.0011859399 | G17: 35668 | H17: 70182.71 | I17: 2502130666 | J17: 107425000 | K17: =I17/H17 -> 35651.668 | L17: =J17/G17 -> 3011.8033
A18: =SCALARS!A19 -> Friday | B18: =SCALARS!B19 -> 46094 | C18: =SCALARS!C19 -> 3013.1842 | D18: =J18/K18 -> 3013.2004 | E18: =C18-C19 -> -0.0173 | F18: =C18-(D18+E18) -> 0.0011497222 | G18: 35701.19 | H18: 71153.47 | I18: 2.5390867e+09 | J18: 107525000 | K18: =I18/H18 -> 35684.65 | L18: =J18/G18 -> 3011.8044
A19: =SCALARS!A20 -> Saturday | B19: =SCALARS!B20 -> 46095 | C19: =SCALARS!C20 -> 3013.2015
A20: =SCALARS!A21 -> Sunday | B20: =SCALARS!B21 -> 46096 | C20: =SCALARS!C21 -> 3013.2188
A21: =SCALARS!A22 -> Monday | B21: =SCALARS!B22 -> 46097 | C21: =SCALARS!C22 -> 3013.2361 | D21: =J21/K21 -> 3013.2177 | E21: =C21-C20 -> 0.0173 | F21: =C21-(D21+E21) -> 0.0011133911 | G21: 35644.71 | H21: 74073.23 | I21: 2.6401892e+09 | J21: 107400000 | K21: =I21/H21 -> 35642.961 | L21: =J21/G21 -> 3013.0698
A22: =SCALARS!A23 -> Tuesday | B22: =SCALARS!B23 -> 46098 | C22: =SCALARS!C23 -> 3013.2534 | D22: =J22/K22 -> 3013.235 | E22: =C22-C21 -> 0.0173 | F22: =C22-(D22+E22) -> 0.0010769842 | G22: 35677.89 | H22: 74681.96 | I22: 2.6643493e+09 | J22: 107500000 | K22: =I22/H22 -> 35675.943 | L22: =J22/G22 -> 3013.0706
A23: =SCALARS!A24 -> Wednesday | B23: =SCALARS!B24 -> 46099 | C23: =SCALARS!C24 -> 3013.2707 | D23: =J23/K23 -> 3013.2524 | E23: =C23-C22 -> 0.0173 | F23: =C23-(D23+E23) -> 0.0010404576 | G23: 35677.89 | H23: 71208.94 | I23: 2.5404314e+09 | J23: 107500000 | K23: =I23/H23 -> 35675.737 | L23: =J23/G23 -> 3013.0706
A24: =SCALARS!A25 -> Thursday | B24: =SCALARS!B25 -> 46100 | C24: =SCALARS!C25 -> 3013.288 | D24: =J24/K24 -> 3013.3044 | E24: =C24-C25 -> -0.0173 | F24: =C24-(D24+E24) -> 0.00093030269 | G24: 35462.18 | H24: 70292.52 | I24: 2.4925314e+09 | J24: 106850000 | K24: =I24/H24 -> 35459.412 | L24: =J24/G24 -> 3013.0691
A25: =SCALARS!A26 -> Friday | B25: =SCALARS!B26 -> 46101 | C25: =SCALARS!C26 -> 3013.3053 | D25: =J25/K25 -> 3013.3217 | E25: =C25-C26 -> -0.0173 | F25: =C25-(D25+E25) -> 0.00089337666 | G25: 35462.18 | H25: 69873.12 | I25: 2.4776455e+09 | J25: 106850000 | K25: =I25/H25 -> 35459.208 | L25: =J25/G25 -> 3013.0691
A26: =SCALARS!A27 -> Saturday | B26: =SCALARS!B27 -> 46102 | C26: =SCALARS!C27 -> 3013.3226
A27: =SCALARS!A28 -> Sunday | B27: =SCALARS!B28 -> 46103 | C27: =SCALARS!C28 -> 3013.3399
A28: =SCALARS!A29 -> Monday | B28: =SCALARS!B29 -> 46104 | C28: =SCALARS!C29 -> 3013.3572 | E28: =C28-C27 -> 0.0173
A29: =SCALARS!A30 -> Tuesday | B29: =SCALARS!B30 -> 46105 | C29: =SCALARS!C30 -> 3013.3745 | D29: =J29/K29 -> 3013.3564 | E29: =C29-C28 -> 0.0173 | F29: =C29-(D29+E29) -> 0.00081924574 | G29: 35329.43 | H29: 69451.67 | I29: 2.4534537e+09 | J29: 106450000 | K29: =I29/H29 -> 35326.057 | L29: =J29/G29 -> 3013.0687
A30: =SCALARS!A31 -> Wednesday | B30: =SCALARS!B31 -> 46106 | C30: =SCALARS!C31 -> 3013.3918 | D30: =J30/K30 -> 3013.3737 | E30: =C30-C29 -> 0.0173 | F30: =C30-(D30+E30) -> 0.00078202957 | G30: 35261.4 | H30: 70883.73 | I30: 2.4992061e+09 | J30: 106245000 | K30: =I30/H30 -> 35257.824 | L30: =J30/G30 -> 3013.0681
A31: =SCALARS!A32 -> Thursday | B31: =SCALARS!B32 -> 46107 | C31: =SCALARS!C32 -> 3013.4091 | D31: =J31/K31 -> 3013.4257 | E31: =C31-C32 -> -0.0173 | F31: =C31-(D31+E31) -> 0.00066977293 | G31: 34816.72 | H31: 68478.86 | I31: 2.383923e+09 | J31: 104905000 | K31: =I31/H31 -> 34812.539 | L31: =J31/G31 -> 3013.0638
A32: =SCALARS!A33 -> Friday | B32: =SCALARS!B33 -> 46108 | C32: =SCALARS!C33 -> 3013.4264 | E32: =C32-C33 -> -0.0173
A33: =SCALARS!A34 -> Saturday | B33: =SCALARS!B34 -> 46109 | C33: =SCALARS!C34 -> 3013.4437
A34: =SCALARS!A35 -> Sunday | B34: =SCALARS!B35 -> 46110 | C34: =SCALARS!C35 -> 3013.461
A35: =SCALARS!A36 -> Monday | B35: =SCALARS!B36 -> 46111 | C35: =SCALARS!C36 -> 3013.4783 | D35: =J35/K35 -> 3013.4604 | E35: =C35-C34 -> 0.0173 | F35: =C35-(D35+E35) -> 0.00059443017 | G35: 35229.99 | H35: 66355.48 | I35: 2.3376109e+09 | J35: 106160000 | K35: =I35/H35 -> 35228.603 | L35: =J35/G35 -> 3013.3418
A36: =SCALARS!A37 -> Tuesday | B36: =SCALARS!B37 -> 46112 | C36: =SCALARS!C37 -> 3013.4956 | D36: =J36/K36 -> 3013.4777 | E36: =C36-C35 -> 0.0173 | F36: =C36-(D36+E36) -> 0.00055660784 | G36: 35246.58 | H36: 67831.76 | I36: 2390729862 | J36: 106210000 | K36: =I36/H36 -> 35244.992 | L36: =J36/G36 -> 3013.342
A37: =SCALARS!A38 -> Wednesday | B37: =SCALARS!B38 -> 46113 | C37: =SCALARS!C38 -> 3013.5129 | D37: =J37/K37 -> 3013.5471 | E37: =C37-C36 -> 0.0173 | G37: 35246.58 | H37: 68149.22 | I37: 2.4018635e+09 | J37: 106210000 | K37: =I37/H37 -> 35244.181 | L37: =J37/G37 -> 3013.342
A38: =SCALARS!A39 -> Thursday | B38: =SCALARS!B39 -> 46114 | C38: =SCALARS!C39 -> 3013.5302 | D38: =J38/K38 -> 3013.5644 | E38: =C38-C39 -> -0.0173 | G38: 35246.58 | H38: 66994.87 | I38: 2.3611658e+09 | J38: 106210000 | K38: =I38/H38 -> 35243.978 | L38: =J38/G38 -> 3013.342
A39: =SCALARS!A40 -> Friday | B39: =SCALARS!B40 -> 46115 | C39: =SCALARS!C40 -> 3013.5475 | E39: =C39-C40 -> -0.0173 | F39: HOLIDAY
A40: =SCALARS!A41 -> Saturday | B40: =SCALARS!B41 -> 46116 | C40: =SCALARS!C41 -> 3013.5648
A41: =SCALARS!A42 -> Sunday | B41: =SCALARS!B42 -> 46117 | C41: =SCALARS!C42 -> 3013.5821
A42: =SCALARS!A43 -> Monday | B42: =SCALARS!B43 -> 46118 | C42: =SCALARS!C43 -> 3013.5994 | D42: =J42/K42 -> 3013.5818 | E42: =C42-C41 -> 0.0173 | F42: =C42-(D42+E42) -> 0.00032765429 | G42: 36948.88 | H42: 69766.87 | I42: 2.5776116e+09 | J42: 111340000 | K42: =I42/H42 -> 36946.069 | L42: =J42/G42 -> 3013.3525
...

Sheet BTCW
A1: BTCW - Bitcoin ETF | WisdomTree
A5: DOW | B5: Date | C5: TODAY'S RATIO | D5: SHS/ADJ BTC | E5: DIFF | F5: TOTAL ASSETS | G5: SHARES OUTSTANDING | H5: BITCOIN IN TRUST | I5: REF PRICE | J5: ADJ BTC | K5: SHS/BTC
A6: =SCALARS!A7 -> Sunday | B6: =SCALARS!B7 -> 46082 | C6: =SCALARS!G7 -> 945.3954
A7: =SCALARS!A8 -> Monday | B7: =SCALARS!B8 -> 46083 | C7: =SCALARS!G8 -> 945.4019
A8: =SCALARS!A9 -> Tuesday | B8: =SCALARS!B9 -> 46084 | C8: =SCALARS!G9 -> 945.4084
A9: =SCALARS!A10 -> Wednesday | B9: =SCALARS!B10 -> 46085 | C9: =SCALARS!G10 -> 945.4149
A10: =SCALARS!A11 -> Thursday | B10: =SCALARS!B11 -> 46086 | C10: =SCALARS!G11 -> 945.4214
A11: =SCALARS!A12 -> Friday | B11: =SCALARS!B12 -> 46087 | C11: =SCALARS!G12 -> 945.4279
A12: =SCALARS!A13 -> Saturday | B12: =SCALARS!B13 -> 46088 | C12: =SCALARS!G13 -> 945.4344
A13: =SCALARS!A14 -> Sunday | B13: =SCALARS!B14 -> 46089 | C13: =SCALARS!G14 -> 945.4409
A14: =SCALARS!A15 -> Monday | B14: =SCALARS!B15 -> 46090 | C14: =SCALARS!G15 -> 945.4474 | D14: =G14/J14 -> 945.44608 | E14: =C14-D14 -> 0.0013206133 | F14: 148956.67 | G14: 2045000 | H14: 2163 | I14: =ARKB!H14 -> 68865.77 | J14: =1000*F14/I14 -> 2163.0001 | K14: =G14/H14 -> 945.44614
A15: =SCALARS!A16 -> Tuesday | B15: =SCALARS!B16 -> 46091 | C15: =SCALARS!G16 -> 945.4539 | D15: =G15/J15 -> 945.45128 | E15: =C15-D15 -> 0.0026161758 | F15: 151451.03 | G15: 2045000 | H15: 2163 | I15: =ARKB!H15 -> 70019.35 | J15: =1000*F15/I15 -> 2162.9882 | K15: =G15/H15 -> 945.44614
A16: =SCALARS!A17 -> Wednesday | B16: =SCALARS!B17 -> 46092 | C16: =SCALARS!G17 -> 945.4604 | D16: =G16/J16 -> 945.45722 | E16: =C16-D16 -> 0.0031774926 | F16: 152706.94 | G16: 2045000 | I16: =ARKB!H16 -> 70600.43 | J16: =1000*F16/I16 -> 2162.9746
A17: =SCALARS!A18 -> Thursday | B17: =SCALARS!B18 -> 46093 | C17: =SCALARS!G18 -> 945.4669 | D17: =G17/J17 -> 945.46415 | E17: =C17-D17 -> 0.0027502779 | F17: 151802.31 | G17: 2045000 | H17: 2163 | I17: =ARKB!H17 -> 70182.71 | J17: =1000*F17/I17 -> 2162.9588 | K17: =G17/H17 -> 945.44614
A18: =SCALARS!A19 -> Friday | B18: =SCALARS!B19 -> 46094 | C18: =SCALARS!G19 -> 945.4734 | D18: =G18/J18 -> 945.46952 | E18: =C18-D18 -> 0.003881741 | F18: 153901.15 | G18: 2045000 | H18: 2163 | I18: =ARKB!H18 -> 71153.47 | J18: =1000*F18/I18 -> 2162.9465 | K18: =G18/H18 -> 945.44614
A19: =SCALARS!A20 -> Saturday | B19: =SCALARS!B20 -> 46095 | C19: =SCALARS!G20 -> 945.4799 | F19: 0
A20: =SCALARS!A21 -> Sunday | B20: =SCALARS!B21 -> 46096 | C20: =SCALARS!G21 -> 945.4864 | F20: 0
A21: =SCALARS!A22 -> Monday | B21: =SCALARS!B22 -> 46097 | C21: =SCALARS!G22 -> 945.4929 | D21: =G21/J21 -> 945.48507 | E21: =C21-D21 -> 0.0078334826 | F21: 160213.8 | G21: 2045000 | H21: 2163 | I21: =ARKB!H21 -> 74073.23 | J21: =1000*F21/I21 -> 2162.9109 | K21: =G21/H21 -> 945.44614
A22: =SCALARS!A23 -> Tuesday | B22: =SCALARS!B23 -> 46098 | C22: =SCALARS!G23 -> 945.4994 | F22: 0
A23: =SCALARS!A24 -> Wednesday | B23: =SCALARS!B24 -> 46099 | C23: =SCALARS!G24 -> 945.5059 | D23: =G23/J23 -> 945.50241 | E23: =C23-D23 -> 0.0034861887 | F23: 154015.77 | G23: 2045000 | I23: =ARKB!H23 -> 71208.94 | J23: =1000*F23/I23 -> 2162.8713
A24: =SCALARS!A25 -> Thursday | B24: =SCALARS!B25 -> 46100 | C24: =SCALARS!G25 -> 945.5124 | D24: =G24/J24 -> 945.51045 | E24: =C24-D24 -> 0.0019541331 | F24: 152032.38 | G24: 2045000 | I24: =ARKB!H24 -> 70292.52 | J24: =1000*F24/I24 -> 2162.8529
A25: =SCALARS!A26 -> Friday | B25: =SCALARS!B26 -> 46101 | C25: =SCALARS!G26 -> 945.5189 | D25: =G25/J25 -> 945.51764 | E25: =C25-D25 -> 0.0012622806 | F25: 151124.13 | G25: 2045000 | I25: =ARKB!H25 -> 69873.12 | J25: =1000*F25/I25 -> 2162.8364
A26: =SCALARS!A27 -> Saturday | B26: =SCALARS!B27 -> 46102 | C26: =SCALARS!G27 -> 945.5254 | F26: 0
A27: =SCALARS!A28 -> Sunday | B27: =SCALARS!B28 -> 46103 | C27: =SCALARS!G28 -> 945.5319 | F27: 0
A28: =SCALARS!A29 -> Monday | B28: =SCALARS!B29 -> 46104 | C28: =SCALARS!G29 -> 945.5384 | F28: 0
A29: =SCALARS!A30 -> Tuesday | B29: =SCALARS!B30 -> 46105 | C29: =SCALARS!G30 -> 945.5449 | D29: =G29/J29 -> 945.5446 | E29: =C29-D29 -> 0.00030466733 | F29: 150208.32 | G29: 2045000 | I29: =ARKB!H29 -> 69451.67 | J29: =1000*F29/I29 -> 2162.7748
A30: =SCALARS!A31 -> Wednesday | B30: =SCALARS!B31 -> 46106 | C30: =SCALARS!G31 -> 945.5514 | D30: =G30/J30 -> 945.54782 | E30: =C30-D30 -> 0.0035774303 | F30: 153305.02 | G30: 2045000 | I30: =ARKB!H30 -> 70883.73 | J30: =1000*F30/I30 -> 2162.7674
A31: =SCALARS!A32 -> Thursday | B31: =SCALARS!B32 -> 46107 | C31: =SCALARS!G32 -> 945.5579 | D31: =G31/J31 -> 945.56005 | E31: =C31-D31 -> -0.0021524585 | F31: 148101.93 | G31: 2045000 | H31: 2163 | I31: =ARKB!H31 -> 68478.86 | J31: =1000*F31/I31 -> 2162.7394
A32: =SCALARS!A33 -> Friday | B32: =SCALARS!B33 -> 46108 | C32: =SCALARS!G33 -> 945.5644 | F32: 0
A33: =SCALARS!A34 -> Saturday | B33: =SCALARS!B34 -> 46109 | C33: =SCALARS!G34 -> 945.5709 | F33: 0
A34: =SCALARS!A35 -> Sunday | B34: =SCALARS!B35 -> 46110 | C34: =SCALARS!G35 -> 945.5774 | F34: 0
A35: =SCALARS!A36 -> Monday | B35: =SCALARS!B36 -> 46111 | C35: =SCALARS!G36 -> 945.5839 | D35: =G35/J35 -> 945.59143 | E35: =C35-D35 -> -0.0075319272 | F35: 143504.85 | G35: 2045000 | H35: 2163 | I35: =ARKB!H35 -> 66355.48 | J35: =1000*F35/I35 -> 2162.6677
A36: =SCALARS!A37 -> Tuesday | B36: =SCALARS!B37 -> 46112 | C36: =SCALARS!G37 -> 945.5904 | D36: =G36/J36 -> 945.59339 | E36: =C36-D36 -> -0.0029850157 | F36: 146697.25 | G36: 2045000 | I36: =ARKB!H36 -> 67831.76 | J36: =1000*F36/I36 -> 2162.6632
A37: =SCALARS!A38 -> Wednesday | B37: =SCALARS!B38 -> 46113 | C37: =SCALARS!G38 -> 945.5969 | D37: =G37/J37 -> 945.5989 | E37: =C37-D37 -> -0.0019966159 | F37: 147382.95 | G37: 2045000 | H37: 2163 | I37: =ARKB!H37 -> 68149.22 | J37: =1000*F37/I37 -> 2162.6506 | K37: =G37/H37 -> 945.44614
A38: =SCALARS!A39 -> Thursday | B38: =SCALARS!B39 -> 46114 | C38: =SCALARS!G39 -> 945.6034 | D38: =G38/J38 -> 945.60904 | E38: =C38-D38 -> -0.0056408706 | F38: 144884.94 | G38: 2045000 | H38: 2163 | I38: =ARKB!H38 -> 66994.87 | J38: =1000*F38/I38 -> 2162.6274 | K38: =G38/H38 -> 945.44614
A39: =SCALARS!A40 -> Friday | B39: =SCALARS!B40 -> 46115 | C39: =SCALARS!G40 -> 945.6099 | F39: 0
A40: =SCALARS!A41 -> Saturday | B40: =SCALARS!B41 -> 46116 | C40: =SCALARS!G41 -> 945.6164 | F40: 0
A41: =SCALARS!A42 -> Sunday | B41: =SCALARS!B42 -> 46117 | C41: =SCALARS!G42 -> 945.6229 | F41: 0
A42: =SCALARS!A43 -> Monday | B42: =SCALARS!B43 -> 46118 | C42: =SCALARS!G43 -> 945.6294 | D42: =G42/J42 -> 945.63708 | E42: =C42-D42 -> -0.0076759105 | F42: 150875.27 | G42: 2045000 | H42: 2163 | I42: =ARKB!H42 -> 69766.87 | J42: =1000*F42/I42 -> 2162.5633 | K42: =G42/H42 -> 945.44614
A43: =SCALARS!A44 -> Tuesday | B43: =SCALARS!B44 -> 46119 | C43: =SCALARS!G44 -> 945.6359 | D43: =G43/J43 -> 945.64426 | E43: =C43-D43 -> -0.0083614382 | F43: 148377.42 | G43: 2045000 | H43: 2163 | I43: =ARKB!H43 -> 68612.35 | J43: =1000*F43/I43 -> 2162.5468 | K43: =G43/H43 -> 945.44614
...

Sheet BITB
A1: https://bitbetf.com
A5: DOW | B5: Date | C5: TODAY'S RATIO | D5: SHS/ADJ BTC | E5: DIFF | F5: NET ASSETS (AUM) | G5: SHARES OUTSTANDING | H5: BITCOIN IN TRUST | I5: BITCOIN PER SHARE | J5: REF PRICE | K5: ADJ BTC | L5: ROUND DOWN BTC / SH | M5: ROUND UP BTC/SH | N5: HIGH BOUND SHS/BTC | O5: LOW BOUND SHS/BTC | P5: SHS/BTC
A6: =SCALARS!A7 -> Sunday | B6: =SCALARS!B7 -> 46082 | C6: =SCALARS!D7 -> 1840.9691
A7: =SCALARS!A8 -> Monday | B7: =SCALARS!B8 -> 46083 | C7: =SCALARS!D8 -> 1840.9792
A8: =SCALARS!A9 -> Tuesday | B8: =SCALARS!B9 -> 46084 | C8: =SCALARS!D9 -> 1840.9893
A9: =SCALARS!A10 -> Wednesday | B9: =SCALARS!B10 -> 46085 | C9: =SCALARS!D10 -> 1840.9994
A10: =SCALARS!A11 -> Thursday | B10: =SCALARS!B11 -> 46086 | C10: =SCALARS!D11 -> 1841.0095
A11: =SCALARS!A12 -> Friday | B11: =SCALARS!B12 -> 46087 | C11: =SCALARS!D12 -> 1841.0196
A12: =SCALARS!A13 -> Saturday | B12: =SCALARS!B13 -> 46088 | C12: =SCALARS!D13 -> 1841.0297
A13: =SCALARS!A14 -> Sunday | B13: =SCALARS!B14 -> 46089 | C13: =SCALARS!D14 -> 1841.0398
A14: =SCALARS!A15 -> Monday | B14: =SCALARS!B15 -> 46090 | C14: =SCALARS!D15 -> 1841.0499 | D14: =G14/K14 -> 1841.0329 | E14: =C14-D14 -> 0.016994513 | F14: 2664058923 | G14: 71220000 | H14: 38686.95 | I14: 0.000543 | J14: 68865.77 | K14: =F14/J14 -> 38684.806 | L14: =I14-0.0000005 -> 0.0005425 | M14: =I14+0.0000005 -> 0.0005435 | N14: =1/L14 -> 1843.318 | O14: =1/M14 -> 1839.9264 | P14: =1/I14 -> 1841.6206
A15: =SCALARS!A16 -> Tuesday | B15: =SCALARS!B16 -> 46091 | C15: =SCALARS!D16 -> 1841.06 | D15: =G15/K15 -> 1841.0415 | E15: =C15-D15 -> 0.018516298 | F15: 2725026281 | G15: 71650000 | H15: 38920.51 | I15: 0.000543 | J15: 70019.35 | K15: =F15/J15 -> 38918.189 | L15: =I15-0.0000005 -> 0.0005425 | M15: =I15+0.0000005 -> 0.0005435 | N15: =1/L15 -> 1843.318 | O15: =1/M15 -> 1839.9264 | P15: =1/I15 -> 1841.6206
A16: =SCALARS!A17 -> Wednesday | B16: =SCALARS!B17 -> 46092 | C16: =SCALARS!D17 -> 1841.0701 | D16: =G16/K16 -> 1841.0507 | E16: =C16-D16 -> 0.019352128 | F16: 2747627036 | G16: 71650000 | H16: 38920.51 | I16: 0.000543 | J16: =ARKB!H16 -> 70600.43 | K16: =F16/J16 -> 38917.993 | L16: =I16-0.0000005 -> 0.0005425 | M16: =I16+0.0000005 -> 0.0005435 | N16: =1/L16 -> 1843.318 | O16: =1/M16 -> 1839.9264 | P16: =1/I16 -> 1841.6206
A17: =SCALARS!A18 -> Thursday | B17: =SCALARS!B18 -> 46093 | C17: =SCALARS!D18 -> 1841.0802 | D17: =G17/K17 -> 1841.0817 | E17: =C17-D17 -> -0.0014664659 | F17: 2725606287 | G17: 71500000 | H17: 38839.04 | I17: 0.000543 | J17: =ARKB!H17 -> 70182.71 | K17: =F17/J17 -> 38835.866 | L17: =I17-0.0000005 -> 0.0005425 | M17: =I17+0.0000005 -> 0.0005435 | N17: =1/L17 -> 1843.318 | O17: =1/M17 -> 1839.9264 | P17: =1/I17 -> 1841.6206
A18: =SCALARS!A19 -> Friday | B18: =SCALARS!B19 -> 46094 | C18: =SCALARS!D19 -> 1841.0903 | D18: =G18/K18 -> 1841.0901 | E18: =C18-D18 -> 0.00018585247 | F18: 2766385710 | G18: 71580000 | H18: 38882.49 | I18: 0.000543 | J18: =ARKB!H18 -> 71153.47 | K18: =F18/J18 -> 38879.14 | L18: =I18-0.0000005 -> 0.0005425 | M18: =I18+0.0000005 -> 0.0005435 | N18: =1/L18 -> 1843.318 | O18: =1/M18 -> 1839.9264 | P18: =1/I18 -> 1841.6206
A19: =SCALARS!A20 -> Saturday | B19: =SCALARS!B20 -> 46095 | C19: =SCALARS!D20 -> 1841.1004
A20: =SCALARS!A21 -> Sunday | B20: =SCALARS!B21 -> 46096 | C20: =SCALARS!D21 -> 1841.1105
A21: =SCALARS!A22 -> Monday | B21: =SCALARS!B22 -> 46097 | C21: =SCALARS!D22 -> 1841.1206 | D21: =G21/K21 -> 1841.0943 | E21: =C21-D21 -> 0.026260377 | F21: 2882713186 | G21: 71650000 | H21: 38920.51 | I21: 0.000543 | J21: =ARKB!H21 -> 74073.23 | K21: =F21/J21 -> 38917.071 | L21: =I21-0.0000005 -> 0.0005425 | M21: =I21+0.0000005 -> 0.0005435 | N21: =1/L21 -> 1843.318 | O21: =1/M21 -> 1839.9264 | P21: =1/I21 -> 1841.6206
A22: =SCALARS!A23 -> Tuesday | B22: =SCALARS!B23 -> 46098 | C22: =SCALARS!D23 -> 1841.1307 | D22: =G22/K22 -> 1841.1032 | E22: =C22-D22 -> 0.027518533 | F22: 2906389217 | G22: 71650000 | H22: 38920.51 | I22: 0.000543 | J22: =ARKB!H22 -> 74681.96 | K22: =F22/J22 -> 38916.885 | L22: =I22-0.0000005 -> 0.0005425 | M22: =I22+0.0000005 -> 0.0005435 | N22: =1/L22 -> 1843.318 | O22: =1/M22 -> 1839.9264 | P22: =1/I22 -> 1841.6206
A23: =SCALARS!A24 -> Wednesday | B23: =SCALARS!B24 -> 46099 | C23: =SCALARS!D24 -> 1841.1408 | D23: =G23/K23 -> 1841.1212 | E23: =C23-D23 -> 0.019616301 | F23: 2764241152 | G23: 71470000 | H23: 38822.75 | I23: 0.000543 | J23: =ARKB!H23 -> 71208.94 | K23: =F23/J23 -> 38818.738 | L23: =I23-0.0000005 -> 0.0005425 | M23: =I23+0.0000005 -> 0.0005435 | N23: =1/L23 -> 1843.318 | O23: =1/M23 -> 1839.9264 | P23: =1/I23 -> 1841.6206
A24: =SCALARS!A25 -> Thursday | B24: =SCALARS!B25 -> 46100 | C24: =SCALARS!D25 -> 1841.1509 | D24: =G24/K24 -> 1841.1538 | E24: =C24-D24 -> -0.0029173704 | F24: 2711438188 | G24: 71020000 | H24: 38578.33 | I24: 0.000543 | J24: =ARKB!H24 -> 70292.52 | K24: =F24/J24 -> 38573.638 | L24: =I24-0.0000005 -> 0.0005425 | M24: =I24+0.0000005 -> 0.0005435 | N24: =1/L24 -> 1843.318 | O24: =1/M24 -> 1839.9264 | P24: =1/I24 -> 1841.6206
A25: =SCALARS!A26 -> Friday | B25: =SCALARS!B26 -> 46101 | C25: =SCALARS!D26 -> 1841.161 | D25: =G25/K25 -> 1841.1651 | E25: =C25-D25 -> -0.0040705615 | F25: 2695243931 | G25: 71020000 | H25: 38578.33 | I25: 0.000543 | J25: =ARKB!H25 -> 69873.12 | K25: =F25/J25 -> 38573.402 | L25: =I25-0.0000005 -> 0.0005425 | M25: =I25+0.0000005 -> 0.0005435 | N25: =1/L25 -> 1843.318 | O25: =1/M25 -> 1839.9264 | P25: =1/I25 -> 1841.6206
A26: =SCALARS!A27 -> Saturday | B26: =SCALARS!B27 -> 46102 | C26: =SCALARS!D27 -> 1841.1711
A27: =SCALARS!A28 -> Sunday | B27: =SCALARS!B28 -> 46103 | C27: =SCALARS!D28 -> 1841.1812
A28: =SCALARS!A29 -> Monday | B28: =SCALARS!B29 -> 46104 | C28: =SCALARS!D29 -> 1841.1913
A29: =SCALARS!A30 -> Tuesday | B29: =SCALARS!B30 -> 46105 | C29: =SCALARS!D30 -> 1841.2014 | D29: =G29/K29 -> 1841.1869 | E29: =C29-D29 -> 0.014537072 | F29: 2662358160 | G29: 70580000 | H29: 38339.35 | I29: 0.000543 | J29: =ARKB!H29 -> 69451.67 | K29: =F29/J29 -> 38333.969 | L29: =I29-0.0000005 -> 0.0005425 | M29: =I29+0.0000005 -> 0.0005435 | N29: =1/L29 -> 1843.318 | O29: =1/M29 -> 1839.9264 | P29: =1/I29 -> 1841.6206
A30: =SCALARS!A31 -> Wednesday | B30: =SCALARS!B31 -> 46106 | C30: =SCALARS!D31 -> 1841.2115 | D30: =G30/K30 -> 1841.1919 | E30: =C30-D30 -> 0.019571018 | F30: 2717247227 | G30: 70580000 | H30: 38339.35 | I30: 0.000543 | J30: =ARKB!H30 -> 70883.73 | K30: =F30/J30 -> 38333.863 | L30: =I30-0.0000005 -> 0.0005425 | M30: =I30+0.0000005 -> 0.0005435 | N30: =1/L30 -> 1843.318 | O30: =1/M30 -> 1839.9264 | P30: =1/I30 -> 1841.6206
A31: =SCALARS!A32 -> Thursday | B31: =SCALARS!B32 -> 46107 | C31: =SCALARS!D32 -> 1841.2216 | D31: =G31/K31 -> 1841.2312 | E31: =C31-D31 -> -0.0096253265 | F31: 2591902466 | G31: 69690000 | H31: 37855.97 | I31: 0.000543 | J31: =ARKB!H31 -> 68478.86 | K31: =F31/J31 -> 37849.673 | L31: =I31-0.0000005 -> 0.0005425 | M31: =I31+0.0000005 -> 0.0005435 | N31: =1/L31 -> 1843.318 | O31: =1/M31 -> 1839.9264 | P31: =1/I31 -> 1841.6206
A32: =SCALARS!A33 -> Friday | B32: =SCALARS!B33 -> 46108 | C32: =SCALARS!D33 -> 1841.2317 | D32: =G32/K32 -> 1841.2524 | E32: =C32-D32 -> -0.02067602 | F32: 2473496849 | G32: 69170000 | H32: 37573.55 | I32: 0.000543 | J32: 65842.59 | K32: =F32/J32 -> 37566.822 | L32: =I32-0.0000005 -> 0.0005425 | M32: =I32+0.0000005 -> 0.0005435 | N32: =1/L32 -> 1843.318 | O32: =1/M32 -> 1839.9264 | P32: =1/I32 -> 1841.6206
A33: =SCALARS!A34 -> Saturday | B33: =SCALARS!B34 -> 46109 | C33: =SCALARS!D34 -> 1841.2418
A34: =SCALARS!A35 -> Sunday | B34: =SCALARS!B35 -> 46110 | C34: =SCALARS!D35 -> 1841.2519
A35: =SCALARS!A36 -> Monday | B35: =SCALARS!B36 -> 46111 | C35: =SCALARS!D36 -> 1841.262 | D35: =G35/K35 -> 1841.2601 | E35: =C35-D35 -> 0.0019227073 | F35: 2492754070 | G35: 69170000 | H35: 37573.55 | I35: 0.000543 | J35: =ARKB!H35 -> 66355.48 | K35: =F35/J35 -> 37566.665 | L35: =I35-0.0000005 -> 0.0005425 | M35: =I35+0.0000005 -> 0.0005435 | N35: =1/L35 -> 1843.318 | O35: =1/M35 -> 1839.9264 | P35: =1/I35 -> 1841.6206
A36: =SCALARS!A37 -> Tuesday | B36: =SCALARS!B37 -> 46112 | C36: =SCALARS!D37 -> 1841.2721 | D36: =G36/K36 -> 1841.263 | E36: =C36-D36 -> 0.0090581862 | F36: 2550050873 | G36: 69220000 | H36: 37593.96 | I36: 0.000543 | J36: =ARKB!H36 -> 67831.76 | K36: =F36/J36 -> 37593.76 | L36: =I36-0.0000005 -> 0.0005425 | M36: =I36+0.0000005 -> 0.0005435 | N36: =1/L36 -> 1843.318 | O36: =1/M36 -> 1839.9264 | P36: =1/I36 -> 1841.6206
A37: =SCALARS!A38 -> Wednesday | B37: =SCALARS!B38 -> 46113 | C37: =SCALARS!D38 -> 1841.2822 | D37: =G37/K37 -> 1841.3034 | E37: =C37-D37 -> -0.021199521 | F37: 2556377524 | G37: 69070000 | H37: 37512.49 | I37: 0.000543 | J37: =ARKB!H37 -> 68149.22 | K37: =F37/J37 -> 37511.472 | L37: =I37-0.0000005 -> 0.0005425 | M37: =I37+0.0000005 -> 0.0005435 | N37: =1/L37 -> 1843.318 | O37: =1/M37 -> 1839.9264 | P37: =1/I37 -> 1841.6206
A38: =SCALARS!A39 -> Thursday | B38: =SCALARS!B39 -> 46114 | C38: =SCALARS!D39 -> 1841.2923 | D38: =G38/K38 -> 1841.3137 | E38: =C38-D38 -> -0.021362991 | F38: 2513062149 | G38: 69070000 | H38: 37512.49 | I38: 0.000543 | J38: =ARKB!H38 -> 66994.87 | K38: =F38/J38 -> 37511.262 | L38: =I38-0.0000005 -> 0.0005425 | M38: =I38+0.0000005 -> 0.0005435 | N38: =1/L38 -> 1843.318 | O38: =1/M38 -> 1839.9264 | P38: =1/I38 -> 1841.6206
A39: =SCALARS!A40 -> Friday | B39: =SCALARS!B40 -> 46115 | C39: =SCALARS!D40 -> 1841.3024 | E39: HOLIDAY
A40: =SCALARS!A41 -> Saturday | B40: =SCALARS!B41 -> 46116 | C40: =SCALARS!D41 -> 1841.3125
A41: =SCALARS!A42 -> Sunday | B41: =SCALARS!B42 -> 46117 | C41: =SCALARS!D42 -> 1841.3226
A42: =SCALARS!A43 -> Monday | B42: =SCALARS!B43 -> 46118 | C42: =SCALARS!D43 -> 1841.3327 | D42: =G42/K42 -> 1841.3217 | E42: =C42-D42 -> 0.010956733 | F42: 2620820840 | G42: 69170000 | H42: 37566.8 | I42: 0.000543 | J42: =ARKB!H42 -> 69766.87 | K42: =F42/J42 -> 37565.407 | L42: =I42-0.0000005 -> 0.0005425 | M42: =I42+0.0000005 -> 0.0005435 | N42: =1/L42 -> 1843.318 | O42: =1/M42 -> 1839.9264 | P42: =1/I42 -> 1841.6206
A43: =SCALARS!A44 -> Tuesday | B43: =SCALARS!B44 -> 46119 | C43: =SCALARS!D44 -> 1841.3428 | D43: =G43/K43 -> 1841.3328 | E43: =C43-D43 -> 0.0099801264 | F43: 2577435322 | G43: 69170000 | H43: 37566.8 | I43: 0.000543 | J43: =ARKB!H43 -> 68612.35 | K43: =F43/J43 -> 37565.181 | L43: =I43-0.0000005 -> 0.0005425 | M43: =I43+0.0000005 -> 0.0005435 | N43: =1/L43 -> 1843.318 | O43: =1/M43 -> 1839.9264 | P43: =1/I43 -> 1841.6206
...

Sheet BRRR
A1: Bitcoin ETF | BRRR | CoinShares Valkyrie ETF
A5: DOW | B5: Date | C5: TODAY'S RATIO | D5: SHS/BTC | E5: DIFF | F5: SHS/ADJ BTC | G5: BITCOIN SHARES | H5: REF PRICE | I5: NET ASSETS | J5: CASH AND OTHER | K5: SHARES OUTSTANDING | L5: ADJ BTC
A6: =SCALARS!A7 -> Sunday | B6: =SCALARS!B7 -> 46082 | C6: =SCALARS!E7 -> 3543.8163
A7: =SCALARS!A8 -> Monday | B7: =SCALARS!B8 -> 46083 | C7: =SCALARS!E8 -> 3543.8406
A8: =SCALARS!A9 -> Tuesday | B8: =SCALARS!B9 -> 46084 | C8: =SCALARS!E9 -> 3543.8649
A9: =SCALARS!A10 -> Wednesday | B9: =SCALARS!B10 -> 46085 | C9: =SCALARS!E10 -> 3543.8892
A10: =SCALARS!A11 -> Thursday | B10: =SCALARS!B11 -> 46086 | C10: =SCALARS!E11 -> 3543.9135
A11: =SCALARS!A12 -> Friday | B11: =SCALARS!B12 -> 46087 | C11: =SCALARS!E12 -> 3543.9378
A12: =SCALARS!A13 -> Saturday | B12: =SCALARS!B13 -> 46088 | C12: =SCALARS!E13 -> 3543.9621
A13: =SCALARS!A14 -> Sunday | B13: =SCALARS!B14 -> 46089 | C13: =SCALARS!E14 -> 3543.9864
A14: =SCALARS!A15 -> Monday | B14: =SCALARS!B15 -> 46090 | C14: =SCALARS!E15 -> 3544.0107 | D14: =K14/G14 -> 3544.0384 | E14: =C14-D14 -> -0.027689602 | G14: 6228.77 | H14: 68865.77 | I14: 4.3303273e+08 | K14: 22075000
A15: =SCALARS!A16 -> Tuesday | B15: =SCALARS!B16 -> 46091 | C15: =SCALARS!E16 -> 3544.035 | D15: =K15/G15 -> 3544.0611 | E15: =C15-D15 -> -0.026148902 | F15: =K15/L15 -> 3544.0374 | G15: 6228.73 | H15: 70019.35 | I15: 4.3613454e+08 | K15: 22075000 | L15: =I15/H15 -> 6228.7717
A16: =SCALARS!A17 -> Wednesday | B16: =SCALARS!B17 -> 46092 | C16: =SCALARS!E17 -> 3544.0593 | D16: =K16/G16 -> 3544.0839 | E16: =C16-D16 -> -0.024608494 | F16: =K16/L16 -> 3544.0617 | G16: 6228.69 | H16: 70600.43 | I16: 4.3975095e+08 | K16: 22075000 | L16: =I16/H16 -> 6228.729
A17: =SCALARS!A18 -> Thursday | B17: =SCALARS!B18 -> 46093 | C17: =SCALARS!E18 -> 3544.0836 | D17: =K17/G17 -> 3544.1124 | E17: =C17-D17 -> -0.028758396 | F17: =K17/L17 -> 3544.086 | G17: 6228.64 | H17: 70182.71 | I17: 4.3714609e+08 | K17: 22075000 | L17: =I17/H17 -> 6228.6863
A18: =SCALARS!A19 -> Friday | B18: =SCALARS!B19 -> 46094 | C18: =SCALARS!E19 -> 3544.1079
A19: =SCALARS!A20 -> Saturday | B19: =SCALARS!B20 -> 46095 | C19: =SCALARS!E20 -> 3544.1322
A20: =SCALARS!A21 -> Sunday | B20: =SCALARS!B21 -> 46096 | C20: =SCALARS!E21 -> 3544.1565
A21: =SCALARS!A22 -> Monday | B21: =SCALARS!B22 -> 46097 | C21: =SCALARS!E22 -> 3544.1808 | G21: 6228.52 | H21: =ARKB!H21 -> 74073.23 | I21: 4.6136628e+08
A22: =SCALARS!A23 -> Tuesday | B22: =SCALARS!B23 -> 46098 | C22: =SCALARS!E23 -> 3544.2051 | D22: =K22/G22 -> 3544.2063 | E22: =C22-D22 -> -0.0011815962 | F22: =K22/L22 -> 3544.1906 | G22: 6256.69 | H22: =ARKB!H22 -> 74681.96 | I22: 4.6345528e+08 | K22: 22175000 | L22: =I22/H21 -> 6256.7176
A23: =SCALARS!A24 -> Wednesday | B23: =SCALARS!B24 -> 46099 | C23: =SCALARS!E24 -> 3544.2294 | D23: =K23/G23 -> 3544.2289 | E23: =C23-D23 -> 0.00045959259 | F23: =K23/L23 -> 3544.1998 | G23: 6256.65 | H23: =ARKB!H23 -> 71208.94 | I23: 467262730 | K23: 22175000 | L23: =I23/H22 -> 6256.7015
A24: =SCALARS!A25 -> Thursday | B24: =SCALARS!B25 -> 46100 | C24: =SCALARS!E25 -> 3544.2537 | D24: =K24/G24 -> 3544.2536 | E24: =C24-D24 -> 0.00011964534 | F24: =K24/L24 -> 3544.2321 | G24: 6301.75 | H24: =ARKB!H24 -> 70292.52 | I24: 4.4874365e+08 | K24: 22335000 | L24: =I24/H23 -> 6301.7881
A25: =SCALARS!A26 -> Friday | B25: =SCALARS!B26 -> 46101 | C25: =SCALARS!E26 -> 3544.278 | D25: =K25/G25 -> 3544.2817 | F25: =K25/L25 -> 3544.256 | G25: 6301.7 | H25: =H24 -> 70292.52 | I25: 442965588 | K25: 22335000 | L25: =I25/H24 -> 6301.7457
A26: =SCALARS!A27 -> Saturday | B26: =SCALARS!B27 -> 46102 | C26: =SCALARS!E27 -> 3544.3023
A27: =SCALARS!A28 -> Sunday | B27: =SCALARS!B28 -> 46103 | C27: =SCALARS!E28 -> 3544.3266
A28: =SCALARS!A29 -> Monday | B28: =SCALARS!B29 -> 46104 | C28: =SCALARS!E29 -> 3544.3509
A29: =SCALARS!A30 -> Tuesday | B29: =SCALARS!B30 -> 46105 | C29: =SCALARS!E30 -> 3544.3752 | D29: =K29/G29 -> 3544.3998 | E29: =C29-D29 -> -0.024616551 | G29: 6301.49 | H29: 69451.67 | I29: 4.3765209e+08 | K29: 22335000
A30: =SCALARS!A31 -> Wednesday | B30: =SCALARS!B31 -> 46106 | C30: =SCALARS!E31 -> 3544.3995 | D30: =K30/G30 -> 3544.4279 | E30: =C30-D30 -> -0.02844028 | F30: =K30/L30 -> 3544.3992 | G30: 6301.44 | H30: 70883.73 | I30: 446673198 | K30: 22335000 | L30: =I30/H30 -> 6301.4912
A31: =SCALARS!A32 -> Thursday | B31: =SCALARS!B32 -> 46107 | C31: =SCALARS!E32 -> 3544.4238 | D31: =K31/G31 -> 3544.4504 | E31: =C31-D31 -> -0.026639585 | F31: =K31/L31 -> 3544.4178 | G31: 6301.4 | H31: 68478.86 | I31: 431516667 | K31: 22335000 | L31: =I31/H31 -> 6301.4581
A32: =SCALARS!A33 -> Friday | B32: =SCALARS!B33 -> 46108 | C32: =SCALARS!E33 -> 3544.4481 | D32: =K32/G32 -> 3544.4504 | F32: =K32/L32 -> 3407.9663 | G32: 6301.4 | H32: 65842.59 | I32: 431516667 | K32: 22335000 | L32: =I32/H32 -> 6553.762
A33: =SCALARS!A34 -> Saturday | B33: =SCALARS!B34 -> 46109 | C33: =SCALARS!E34 -> 3544.4724
A34: =SCALARS!A35 -> Sunday | B34: =SCALARS!B35 -> 46110 | C34: =SCALARS!E35 -> 3544.4967
A35: =SCALARS!A36 -> Monday | B35: =SCALARS!B36 -> 46111 | C35: =SCALARS!E36 -> 3544.521 | D35: =K35/G35 -> 3544.5461 | E35: =C35-D35 -> -0.025064816 | F35: =K35/L35 -> 3544.5167 | G35: 6301.23 | H35: 66355.48 | I35: 418124601 | K35: 22335000 | L35: =I35/H35 -> 6301.2821
A36: =SCALARS!A37 -> Tuesday | B36: =SCALARS!B37 -> 46112 | C36: =SCALARS!E37 -> 3544.5453 | D36: =K36/G36 -> 3544.5742 | E36: =C36-D36 -> -0.028890866 | F36: =K36/L36 -> 3544.5532 | G36: 6301.18 | H36: 67831.76 | I36: 4.2742266e+08 | K36: 22335000 | L36: =I36/H36 -> 6301.2173 | N36: =D35 -> 3544.5461 | O36: =+C36-N36 -> -0.00076481592
A37: =SCALARS!A38 -> Wednesday | B37: =SCALARS!B38 -> 46113 | C37: =SCALARS!E38 -> 3544.5696 | D37: =K37/G37 -> 3544.5967 | E37: =C37-D37 -> -0.027092027 | F37: =K37/L37 -> 3544.5648 | G37: 6301.14 | H37: 68149.22 | I37: 429421644 | K37: 22335000 | L37: =I37/H37 -> 6301.1968 | N37: =D36 -> 3544.5742 | O37: =+C37-N37 -> -0.0045908658
A38: =SCALARS!A39 -> Thursday | B38: =SCALARS!B39 -> 46114 | C38: =SCALARS!E39 -> 3544.5939 | D38: =K38/G38 -> 3544.6923 | F38: =K38/L38 -> 3544.5896 | G38: 6300.97 | H38: 66994.87 | I38: 422144901 | K38: 22335000 | L38: =I38/H38 -> 6301.1526 | N38: =D37 -> 3544.5967 | O38: =+C38-N38 -> -0.0027920272
A39: =SCALARS!A40 -> Friday | B39: =SCALARS!B40 -> 46115 | C39: =SCALARS!E40 -> 3544.6182 | E39: HOLIDAY
A40: =SCALARS!A41 -> Saturday | B40: =SCALARS!B41 -> 46116 | C40: =SCALARS!E41 -> 3544.6425
A41: =SCALARS!A42 -> Sunday | B41: =SCALARS!B42 -> 46117 | C41: =SCALARS!E42 -> 3544.6668
A42: =SCALARS!A43 -> Monday | B42: =SCALARS!B43 -> 46118 | C42: =SCALARS!E43 -> 3544.6911 | D42: =K42/G42 -> 3544.7166 | E42: =C42-D42 -> -0.025527886 | F42: =K42/L42 -> 3544.6863 | G42: 6334.78 | H42: 69766.87 | I42: 4.4196156e+08 | K42: 22455000 | L42: =I42/H42 -> 6334.8342
A43: =SCALARS!A44 -> Tuesday | B43: =SCALARS!B44 -> 46119 | C43: =SCALARS!E44 -> 3544.7154 | D43: =K43/G43 -> 3544.739 | E43: =C43-D43 -> -0.023610599 | F43: =K43/L43 -> 3544.7221 | G43: 6334.74 | H43: 68612.35 | I43: 434643471 | K43: 22455000 | L43: =I43/H43 -> 6334.7702 | N43: =D42 -> 3544.7166 | O43: =+C43-N43 -> -0.0012278861
...

Sheet BTC
A1: https://etfs.grayscale.com/btc
A5: DAY OF WEEK | B5: DATE | C5: TODAY'S RATIO | D5: SHS/BTC | E5: DIFF | F5: BITCOIN PER SHARE | H5: ALT SHS/BTC | I5: SHARES OUTSTANDING | J5: TOTAL BITCOIN IN TRUST
A6: =SCALARS!A7 -> Sunday | B6: =SCALARS!B7 -> 46082 | C6: =SCALARS!F7 -> 2260.2814
A7: =SCALARS!A8 -> Monday | B7: =SCALARS!B8 -> 46083 | C7: =SCALARS!F8 -> 2260.2907
A8: =SCALARS!A9 -> Tuesday | B8: =SCALARS!B9 -> 46084 | C8: =SCALARS!F9 -> 2260.3
A9: =SCALARS!A10 -> Wednesday | B9: =SCALARS!B10 -> 46085 | C9: =SCALARS!F10 -> 2260.3093
A10: =SCALARS!A11 -> Thursday | B10: =SCALARS!B11 -> 46086 | C10: =SCALARS!F11 -> 2260.3186
A11: =SCALARS!A12 -> Friday | B11: =SCALARS!B12 -> 46087 | C11: =SCALARS!F12 -> 2260.3279
A12: =SCALARS!A13 -> Saturday | B12: =SCALARS!B13 -> 46088 | C12: =SCALARS!F13 -> 2260.3372
A13: =SCALARS!A14 -> Sunday | B13: =SCALARS!B14 -> 46089 | C13: =SCALARS!F14 -> 2260.3465
A14: =SCALARS!A15 -> Monday | B14: =SCALARS!B15 -> 46090 | C14: =SCALARS!F15 -> 2260.3558 | D14: =1/F14 -> 2260.3467 | E14: =C14-D14 -> 0.0090628105 | F14: 0.00044241 | H14: =I14/J14 -> 2260.3551 | I14: 116349963 | J14: 51474.196
A15: =SCALARS!A16 -> Tuesday | B15: =SCALARS!B16 -> 46091 | C15: =SCALARS!F16 -> 2260.3651 | D15: =1/F15 -> 2260.3467 | E15: =C15-D15 -> 0.018362811 | F15: 0.00044241 | H15: =I15/J15 -> 2260.3644 | I15: 116349963 | J15: 51473.984
A16: =SCALARS!A17 -> Wednesday | B16: =SCALARS!B17 -> 46092 | C16: =SCALARS!F17 -> 2260.3744 | D16: =1/F16 -> 2260.3978 | E16: =C16-D16 -> -0.023430018 | F16: 0.0004424 | H16: =I16/J16 -> 2260.3737 | I16: 116519963 | J16: 51548.982
A17: =SCALARS!A18 -> Thursday | B17: =SCALARS!B18 -> 46093 | C17: =SCALARS!F18 -> 2260.3837 | D17: =1/F17 -> 2260.3978 | E17: =C17-D17 -> -0.014130018 | F17: 0.0004424 | H17: =I17/J17 -> 2260.383 | I17: 116679963 | J17: 51619.554
A18: =SCALARS!A19 -> Friday | B18: =SCALARS!B19 -> 46094 | C18: =SCALARS!F19 -> 2260.393 | D18: =1/F18 -> 2260.3978 | E18: =C18-D18 -> -0.0048300181 | F18: 0.0004424 | H18: =I18/J18 -> 2260.3923 | I18: 116839963 | J18: 51690.126
A19: =SCALARS!A20 -> Saturday | B19: =SCALARS!B20 -> 46095 | C19: =SCALARS!F20 -> 2260.4023
A20: =SCALARS!A21 -> Sunday | B20: =SCALARS!B21 -> 46096 | C20: =SCALARS!F21 -> 2260.4116
