Workbook

Sheet Pivot summary
A1: P&L by Pair — normalized source summary (USD)
A2: Asset class / Pair | B2: June 2026 | H2: July 2026 | N2: August 2026 | T2: September 2026 | Z2: October 2026 | AF2: Grand total
B3: MTM P&L | C3: Commissions | D3: Borrow | E3: Dividends / PIL | F3: Other | G3: Net P&L | H3: MTM P&L | I3: Commissions | J3: Borrow | K3: Dividends / PIL | L3: Other | M3: Net P&L | N3: MTM P&L | O3: Commissions | P3: Borrow | Q3: Dividends / PIL | R3: Other | S3: Net P&L | T3: MTM P&L | U3: Commissions | V3: Borrow | W3: Dividends / PIL | X3: Other | Y3: Net P&L | Z3: MTM P&L | AA3: Commissions | AB3: Borrow | AC3: Dividends / PIL | AD3: Other | AE3: Net P&L | AF3: MTM P&L | AG3: Commissions | AH3: Borrow | AI3: Dividends / PIL | AJ3: Other | AK3: Net P&L
A4: EQUITIES
A5: IYW / XLK | B5: =SUMIFS('P&L Table'!$F$2:$F$303,'P&L Table'!$A$2:$A$303,"June",'P&L Table'!$C$2:$C$303,$A5,'P&L Table'!$E$2:$E$303,"MTM P&L") -> 0 | C5: =SUMIFS('P&L Table'!$F$2:$F$303,'P&L Table'!$A$2:$A$303,"June",'P&L Table'!$C$2:$C$303,$A5,'P&L Table'!$E$2:$E$303,"Commissions") -> 0 | D5: =SUMIFS('P&L Table'!$F$2:$F$303,'P&L Table'!$A$2:$A$303,"June",'P&L Table'!$C$2:$C$303,$A5,'P&L Table'!$E$2:$E$303,"Borrow") -> 0 | E5: =SUMIFS('P&L Table'!$F$2:$F$303,'P&L Table'!$A$2:$A$303,"June",'P&L Table'!$C$2:$C$303,$A5,'P&L Table'!$E$2:$E$303,"Dividends / PIL") -> 0 | F5: =SUMIFS('P&L Table'!$F$2:$F$303,'P&L Table'!$A$2:$A$303,"June",'P&L Table'!$C$2:$C$303,$A5,'P&L Table'!$E$2:$E$303,"Other") -> 0 | G5: =SUM(B5:F5) -> 0 | H5: =SUMIFS('P&L Table'!$F$2:$F$303,'P&L Table'!$A$2:$A$303,"July",'P&L Table'!$C$2:$C$303,$A5,'P&L Table'!$E$2:$E$303,"MTM P&L") -> 0 | I5: =SUMIFS('P&L Table'!$F$2:$F$303,'P&L Table'!$A$2:$A$303,"July",'P&L Table'!$C$2:$C$303,$A5,'P&L Table'!$E$2:$E$303,"Commissions") -> 0 | J5: =SUMIFS('P&L Table'!$F$2:$F$303,'P&L Table'!$A$2:$A$303,"July",'P&L Table'!$C$2:$C$303,$A5,'P&L Table'!$E$2:$E$303,"Borrow") -> 0 | K5: =SUMIFS('P&L Table'!$F$2:$F$303,'P&L Table'!$A$2:$A$303,"July",'P&L Table'!$C$2:$C$303,$A5,'P&L Table'!$E$2:$E$303,"Dividends / PIL") -> 0 | L5: =SUMIFS('P&L Table'!$F$2:$F$303,'P&L Table'!$A$2:$A$303,"July",'P&L Table'!$C$2:$C$303,$A5,'P&L Table'!$E$2:$E$303,"Other") -> 0 | M5: =SUM(H5:L5) -> 0 | N5: =SUMIFS('P&L Table'!$F$2:$F$303,'P&L Table'!$A$2:$A$303,"August",'P&L Table'!$C$2:$C$303,$A5,'P&L Table'!$E$2:$E$303,"MTM P&L") -> 0 | O5: =SUMIFS('P&L Table'!$F$2:$F$303,'P&L Table'!$A$2:$A$303,"August",'P&L Table'!$C$2:$C$303,$A5,'P&L Table'!$E$2:$E$303,"Commissions") -> 0 | P5: =SUMIFS('P&L Table'!$F$2:$F$303,'P&L Table'!$A$2:$A$303,"August",'P&L Table'!$C$2:$C$303,$A5,'P&L Table'!$E$2:$E$303,"Borrow") -> 0 | Q5: =SUMIFS('P&L Table'!$F$2:$F$303,'P&L Table'!$A$2:$A$303,"August",'P&L Table'!$C$2:$C$303,$A5,'P&L Table'!$E$2:$E$303,"Dividends / PIL") -> 0 | R5: =SUMIFS('P&L Table'!$F$2:$F$303,'P&L Table'!$A$2:$A$303,"August",'P&L Table'!$C$2:$C$303,$A5,'P&L Table'!$E$2:$E$303,"Other") -> 0 | S5: =SUM(N5:R5) -> 0 | T5: =SUMIFS('P&L Table'!$F$2:$F$303,'P&L Table'!$A$2:$A$303,"September",'P&L Table'!$C$2:$C$303,$A5,'P&L Table'!$E$2:$E$303,"MTM P&L") -> 10454.02 | U5: =SUMIFS('P&L Table'!$F$2:$F$303,'P&L Table'!$A$2:$A$303,"September",'P&L Table'!$C$2:$C$303,$A5,'P&L Table'!$E$2:$E$303,"Commissions") -> -321.5 | V5: =SUMIFS('P&L Table'!$F$2:$F$303,'P&L Table'!$A$2:$A$303,"September",'P&L Table'!$C$2:$C$303,$A5,'P&L Table'!$E$2:$E$303,"Borrow") -> -250.87 | W5: =SUMIFS('P&L Table'!$F$2:$F$303,'P&L Table'!$A$2:$A$303,"September",'P&L Table'!$C$2:$C$303,$A5,'P&L Table'!$E$2:$E$303,"Dividends / PIL") -> 1025.45 | X5: =SUMIFS('P&L Table'!$F$2:$F$303,'P&L Table'!$A$2:$A$303,"September",'P&L Table'!$C$2:$C$303,$A5,'P&L Table'!$E$2:$E$303,"Other") -> 0 | Y5: =SUM(T5:X5) -> 10907.1 | Z5: =SUMIFS('P&L Table'!$F$2:$F$303,'P&L Table'!$A$2:$A$303,"October",'P&L Table'!$C$2:$C$303,$A5,'P&L Table'!$E$2:$E$303,"MTM P&L") -> 1367.82 | AA5: =SUMIFS('P&L Table'!$F$2:$F$303,'P&L Table'!$A$2:$A$303,"October",'P&L Table'!$C$2:$C$303,$A5,'P&L Table'!$E$2:$E$303,"Commissions") -> -149.46 | AB5: =SUMIFS('P&L Table'!$F$2:$F$303,'P&L Table'!$A$2:$A$303,"October",'P&L Table'!$C$2:$C$303,$A5,'P&L Table'!$E$2:$E$303,"Borrow") -> -53.06 | AC5: =SUMIFS('P&L Table'!$F$2:$F$303,'P&L Table'!$A$2:$A$303,"October",'P&L Table'!$C$2:$C$303,$A5,'P&L Table'!$E$2:$E$303,"Dividends / PIL") -> 0 | AD5: =SUMIFS('P&L Table'!$F$2:$F$303,'P&L Table'!$A$2:$A$303,"October",'P&L Table'!$C$2:$C$303,$A5,'P&L Table'!$E$2:$E$303,"Other") -> 0 | AE5: =SUM(Z5:AD5) -> 1165.3 | AF5: =SUM(B5,H5,N5,T5,Z5) -> 11821.84 | AG5: =SUM(C5,I5,O5,U5,AA5) -> -470.96 | AH5: =SUM(D5,J5,P5,V5,AB5) -> -303.93 | AI5: =SUM(E5,K5,Q5,W5,AC5) -> 1025.45 | AJ5: =SUM(F5,L5,R5,X5,AD5) -> 0 | AK5: =SUM(G5,M5,S5,Y5,AE5) -> 12072.4
A6: KBE / KBWB | B6: =SUMIFS('P&L Table'!$F$2:$F$303,'P&L Table'!$A$2:$A$303,"June",'P&L Table'!$C$2:$C$303,$A6,'P&L Table'!$E$2:$E$303,"MTM P&L") -> 0 | C6: =SUMIFS('P&L Table'!$F$2:$F$303,'P&L Table'!$A$2:$A$303,"June",'P&L Table'!$C$2:$C$303,$A6,'P&L Table'!$E$2:$E$303,"Commissions") -> 0 | D6: =SUMIFS('P&L Table'!$F$2:$F$303,'P&L Table'!$A$2:$A$303,"June",'P&L Table'!$C$2:$C$303,$A6,'P&L Table'!$E$2:$E$303,"Borrow") -> 0 | E6: =SUMIFS('P&L Table'!$F$2:$F$303,'P&L Table'!$A$2:$A$303,"June",'P&L Table'!$C$2:$C$303,$A6,'P&L Table'!$E$2:$E$303,"Dividends / PIL") -> 0 | F6: =SUMIFS('P&L Table'!$F$2:$F$303,'P&L Table'!$A$2:$A$303,"June",'P&L Table'!$C$2:$C$303,$A6,'P&L Table'!$E$2:$E$303,"Other") -> 0 | G6: =SUM(B6:F6) -> 0 | H6: =SUMIFS('P&L Table'!$F$2:$F$303,'P&L Table'!$A$2:$A$303,"July",'P&L Table'!$C$2:$C$303,$A6,'P&L Table'!$E$2:$E$303,"MTM P&L") -> 0 | I6: =SUMIFS('P&L Table'!$F$2:$F$303,'P&L Table'!$A$2:$A$303,"July",'P&L Table'!$C$2:$C$303,$A6,'P&L Table'!$E$2:$E$303,"Commissions") -> 0 | J6: =SUMIFS('P&L Table'!$F$2:$F$303,'P&L Table'!$A$2:$A$303,"July",'P&L Table'!$C$2:$C$303,$A6,'P&L Table'!$E$2:$E$303,"Borrow") -> 0 | K6: =SUMIFS('P&L Table'!$F$2:$F$303,'P&L Table'!$A$2:$A$303,"July",'P&L Table'!$C$2:$C$303,$A6,'P&L Table'!$E$2:$E$303,"Dividends / PIL") -> 0 | L6: =SUMIFS('P&L Table'!$F$2:$F$303,'P&L Table'!$A$2:$A$303,"July",'P&L Table'!$C$2:$C$303,$A6,'P&L Table'!$E$2:$E$303,"Other") -> 0 | M6: =SUM(H6:L6) -> 0 | N6: =SUMIFS('P&L Table'!$F$2:$F$303,'P&L Table'!$A$2:$A$303,"August",'P&L Table'!$C$2:$C$303,$A6,'P&L Table'!$E$2:$E$303,"MTM P&L") -> 0 | O6: =SUMIFS('P&L Table'!$F$2:$F$303,'P&L Table'!$A$2:$A$303,"August",'P&L Table'!$C$2:$C$303,$A6,'P&L Table'!$E$2:$E$303,"Commissions") -> 0 | P6: =SUMIFS('P&L Table'!$F$2:$F$303,'P&L Table'!$A$2:$A$303,"August",'P&L Table'!$C$2:$C$303,$A6,'P&L Table'!$E$2:$E$303,"Borrow") -> 0 | Q6: =SUMIFS('P&L Table'!$F$2:$F$303,'P&L Table'!$A$2:$A$303,"August",'P&L Table'!$C$2:$C$303,$A6,'P&L Table'!$E$2:$E$303,"Dividends / PIL") -> 0 | R6: =SUMIFS('P&L Table'!$F$2:$F$303,'P&L Table'!$A$2:$A$303,"August",'P&L Table'!$C$2:$C$303,$A6,'P&L Table'!$E$2:$E$303,"Other") -> 0 | S6: =SUM(N6:R6) -> 0 | T6: =SUMIFS('P&L Table'!$F$2:$F$303,'P&L Table'!$A$2:$A$303,"September",'P&L Table'!$C$2:$C$303,$A6,'P&L Table'!$E$2:$E$303,"MTM P&L") -> 1483 | U6: =SUMIFS('P&L Table'!$F$2:$F$303,'P&L Table'!$A$2:$A$303,"September",'P&L Table'!$C$2:$C$303,$A6,'P&L Table'!$E$2:$E$303,"Commissions") -> -50.5 | V6: =SUMIFS('P&L Table'!$F$2:$F$303,'P&L Table'!$A$2:$A$303,"September",'P&L Table'!$C$2:$C$303,$A6,'P&L Table'!$E$2:$E$303,"Borrow") -> -128.32 | W6: =SUMIFS('P&L Table'!$F$2:$F$303,'P&L Table'!$A$2:$A$303,"September",'P&L Table'!$C$2:$C$303,$A6,'P&L Table'!$E$2:$E$303,"Dividends / PIL") -> 0 | X6: =SUMIFS('P&L Table'!$F$2:$F$303,'P&L Table'!$A$2:$A$303,"September",'P&L Table'!$C$2:$C$303,$A6,'P&L Table'!$E$2:$E$303,"Other") -> 0 | Y6: =SUM(T6:X6) -> 1304.18 | Z6: =SUMIFS('P&L Table'!$F$2:$F$303,'P&L Table'!$A$2:$A$303,"October",'P&L Table'!$C$2:$C$303,$A6,'P&L Table'!$E$2:$E$303,"MTM P&L") -> 853.98 | AA6: =SUMIFS('P&L Table'!$F$2:$F$303,'P&L Table'!$A$2:$A$303,"October",'P&L Table'!$C$2:$C$303,$A6,'P&L Table'!$E$2:$E$303,"Commissions") -> -98.37 | AB6: =SUMIFS('P&L Table'!$F$2:$F$303,'P&L Table'!$A$2:$A$303,"October",'P&L Table'!$C$2:$C$303,$A6,'P&L Table'!$E$2:$E$303,"Borrow") -> -322.73 | AC6: =SUMIFS('P&L Table'!$F$2:$F$303,'P&L Table'!$A$2:$A$303,"October",'P&L Table'!$C$2:$C$303,$A6,'P&L Table'!$E$2:$E$303,"Dividends / PIL") -> 0 | AD6: =SUMIFS('P&L Table'!$F$2:$F$303,'P&L Table'!$A$2:$A$303,"October",'P&L Table'!$C$2:$C$303,$A6,'P&L Table'!$E$2:$E$303,"Other") -> 0 | AE6: =SUM(Z6:AD6) -> 432.88 | AF6: =SUM(B6,H6,N6,T6,Z6) -> 2336.98 | AG6: =SUM(C6,I6,O6,U6,AA6) -> -148.87 | AH6: =SUM(D6,J6,P6,V6,AB6) -> -451.05 | AI6: =SUM(E6,K6,Q6,W6,AC6) -> 0 | AJ6: =SUM(F6,L6,R6,X6,AD6) -> 0 | AK6: =SUM(G6,M6,S6,Y6,AE6) -> 1737.06
A7: IYK / XLP | B7: =SUMIFS('P&L Table'!$F$2:$F$303,'P&L Table'!$A$2:$A$303,"June",'P&L Table'!$C$2:$C$303,$A7,'P&L Table'!$E$2:$E$303,"MTM P&L") -> 0 | C7: =SUMIFS('P&L Table'!$F$2:$F$303,'P&L Table'!$A$2:$A$303,"June",'P&L Table'!$C$2:$C$303,$A7,'P&L Table'!$E$2:$E$303,"Commissions") -> 0 | D7: =SUMIFS('P&L Table'!$F$2:$F$303,'P&L Table'!$A$2:$A$303,"June",'P&L Table'!$C$2:$C$303,$A7,'P&L Table'!$E$2:$E$303,"Borrow") -> 0 | E7: =SUMIFS('P&L Table'!$F$2:$F$303,'P&L Table'!$A$2:$A$303,"June",'P&L Table'!$C$2:$C$303,$A7,'P&L Table'!$E$2:$E$303,"Dividends / PIL") -> 0 | F7: =SUMIFS('P&L Table'!$F$2:$F$303,'P&L Table'!$A$2:$A$303,"June",'P&L Table'!$C$2:$C$303,$A7,'P&L Table'!$E$2:$E$303,"Other") -> 0 | G7: =SUM(B7:F7) -> 0 | H7: =SUMIFS('P&L Table'!$F$2:$F$303,'P&L Table'!$A$2:$A$303,"July",'P&L Table'!$C$2:$C$303,$A7,'P&L Table'!$E$2:$E$303,"MTM P&L") -> 0 | I7: =SUMIFS('P&L Table'!$F$2:$F$303,'P&L Table'!$A$2:$A$303,"July",'P&L Table'!$C$2:$C$303,$A7,'P&L Table'!$E$2:$E$303,"Commissions") -> 0 | J7: =SUMIFS('P&L Table'!$F$2:$F$303,'P&L Table'!$A$2:$A$303,"July",'P&L Table'!$C$2:$C$303,$A7,'P&L Table'!$E$2:$E$303,"Borrow") -> 0 | K7: =SUMIFS('P&L Table'!$F$2:$F$303,'P&L Table'!$A$2:$A$303,"July",'P&L Table'!$C$2:$C$303,$A7,'P&L Table'!$E$2:$E$303,"Dividends / PIL") -> 0 | L7: =SUMIFS('P&L Table'!$F$2:$F$303,'P&L Table'!$A$2:$A$303,"July",'P&L Table'!$C$2:$C$303,$A7,'P&L Table'!$E$2:$E$303,"Other") -> 0 | M7: =SUM(H7:L7) -> 0 | N7: =SUMIFS('P&L Table'!$F$2:$F$303,'P&L Table'!$A$2:$A$303,"August",'P&L Table'!$C$2:$C$303,$A7,'P&L Table'!$E$2:$E$303,"MTM P&L") -> 0 | O7: =SUMIFS('P&L Table'!$F$2:$F$303,'P&L Table'!$A$2:$A$303,"August",'P&L Table'!$C$2:$C$303,$A7,'P&L Table'!$E$2:$E$303,"Commissions") -> 0 | P7: =SUMIFS('P&L Table'!$F$2:$F$303,'P&L Table'!$A$2:$A$303,"August",'P&L Table'!$C$2:$C$303,$A7,'P&L Table'!$E$2:$E$303,"Borrow") -> 0 | Q7: =SUMIFS('P&L Table'!$F$2:$F$303,'P&L Table'!$A$2:$A$303,"August",'P&L Table'!$C$2:$C$303,$A7,'P&L Table'!$E$2:$E$303,"Dividends / PIL") -> 0 | R7: =SUMIFS('P&L Table'!$F$2:$F$303,'P&L Table'!$A$2:$A$303,"August",'P&L Table'!$C$2:$C$303,$A7,'P&L Table'!$E$2:$E$303,"Other") -> 0 | S7: =SUM(N7:R7) -> 0 | T7: =SUMIFS('P&L Table'!$F$2:$F$303,'P&L Table'!$A$2:$A$303,"September",'P&L Table'!$C$2:$C$303,$A7,'P&L Table'!$E$2:$E$303,"MTM P&L") -> 2006.1 | U7: =SUMIFS('P&L Table'!$F$2:$F$303,'P&L Table'!$A$2:$A$303,"September",'P&L Table'!$C$2:$C$303,$A7,'P&L Table'!$E$2:$E$303,"Commissions") -> -113.77 | V7: =SUMIFS('P&L Table'!$F$2:$F$303,'P&L Table'!$A$2:$A$303,"September",'P&L Table'!$C$2:$C$303,$A7,'P&L Table'!$E$2:$E$303,"Borrow") -> -530.93 | W7: =SUMIFS('P&L Table'!$F$2:$F$303,'P&L Table'!$A$2:$A$303,"September",'P&L Table'!$C$2:$C$303,$A7,'P&L Table'!$E$2:$E$303,"Dividends / PIL") -> -960.31 | X7: =SUMIFS('P&L Table'!$F$2:$F$303,'P&L Table'!$A$2:$A$303,"September",'P&L Table'!$C$2:$C$303,$A7,'P&L Table'!$E$2:$E$303,"Other") -> 0 | Y7: =SUM(T7:X7) -> 401.09 | Z7: =SUMIFS('P&L Table'!$F$2:$F$303,'P&L Table'!$A$2:$A$303,"October",'P&L Table'!$C$2:$C$303,$A7,'P&L Table'!$E$2:$E$303,"MTM P&L") -> 0 | AA7: =SUMIFS('P&L Table'!$F$2:$F$303,'P&L Table'!$A$2:$A$303,"October",'P&L Table'!$C$2:$C$303,$A7,'P&L Table'!$E$2:$E$303,"Commissions") -> 0 | AB7: =SUMIFS('P&L Table'!$F$2:$F$303,'P&L Table'!$A$2:$A$303,"October",'P&L Table'!$C$2:$C$303,$A7,'P&L Table'!$E$2:$E$303,"Borrow") -> -2.44 | AC7: =SUMIFS('P&L Table'!$F$2:$F$303,'P&L Table'!$A$2:$A$303,"October",'P&L Table'!$C$2:$C$303,$A7,'P&L Table'!$E$2:$E$303,"Dividends / PIL") -> 0 | AD7: =SUMIFS('P&L Table'!$F$2:$F$303,'P&L Table'!$A$2:$A$303,"October",'P&L Table'!$C$2:$C$303,$A7,'P&L Table'!$E$2:$E$303,"Other") -> 0 | AE7: =SUM(Z7:AD7) -> -2.44 | AF7: =SUM(B7,H7,N7,T7,Z7) -> 2006.1 | AG7: =SUM(C7,I7,O7,U7,AA7) -> -113.77 | AH7: =SUM(D7,J7,P7,V7,AB7) -> -533.37 | AI7: =SUM(E7,K7,Q7,W7,AC7) -> -960.31 | AJ7: =SUM(F7,L7,R7,X7,AD7) -> 0 | AK7: =SUM(G7,M7,S7,Y7,AE7) -> 398.65
A8: FWONA / FWONK | B8: =SUMIFS('P&L Table'!$F$2:$F$303,'P&L Table'!$A$2:$A$303,"June",'P&L Table'!$C$2:$C$303,$A8,'P&L Table'!$E$2:$E$303,"MTM P&L") -> 0 | C8: =SUMIFS('P&L Table'!$F$2:$F$303,'P&L Table'!$A$2:$A$303,"June",'P&L Table'!$C$2:$C$303,$A8,'P&L Table'!$E$2:$E$303,"Commissions") -> 0 | D8: =SUMIFS('P&L Table'!$F$2:$F$303,'P&L Table'!$A$2:$A$303,"June",'P&L Table'!$C$2:$C$303,$A8,'P&L Table'!$E$2:$E$303,"Borrow") -> 0 | E8: =SUMIFS('P&L Table'!$F$2:$F$303,'P&L Table'!$A$2:$A$303,"June",'P&L Table'!$C$2:$C$303,$A8,'P&L Table'!$E$2:$E$303,"Dividends / PIL") -> 0 | F8: =SUMIFS('P&L Table'!$F$2:$F$303,'P&L Table'!$A$2:$A$303,"June",'P&L Table'!$C$2:$C$303,$A8,'P&L Table'!$E$2:$E$303,"Other") -> 0 | G8: =SUM(B8:F8) -> 0 | H8: =SUMIFS('P&L Table'!$F$2:$F$303,'P&L Table'!$A$2:$A$303,"July",'P&L Table'!$C$2:$C$303,$A8,'P&L Table'!$E$2:$E$303,"MTM P&L") -> 0 | I8: =SUMIFS('P&L Table'!$F$2:$F$303,'P&L Table'!$A$2:$A$303,"July",'P&L Table'!$C$2:$C$303,$A8,'P&L Table'!$E$2:$E$303,"Commissions") -> 0 | J8: =SUMIFS('P&L Table'!$F$2:$F$303,'P&L Table'!$A$2:$A$303,"July",'P&L Table'!$C$2:$C$303,$A8,'P&L Table'!$E$2:$E$303,"Borrow") -> 0 | K8: =SUMIFS('P&L Table'!$F$2:$F$303,'P&L Table'!$A$2:$A$303,"July",'P&L Table'!$C$2:$C$303,$A8,'P&L Table'!$E$2:$E$303,"Dividends / PIL") -> 0 | L8: =SUMIFS('P&L Table'!$F$2:$F$303,'P&L Table'!$A$2:$A$303,"July",'P&L Table'!$C$2:$C$303,$A8,'P&L Table'!$E$2:$E$303,"Other") -> 0 | M8: =SUM(H8:L8) -> 0 | N8: =SUMIFS('P&L Table'!$F$2:$F$303,'P&L Table'!$A$2:$A$303,"August",'P&L Table'!$C$2:$C$303,$A8,'P&L Table'!$E$2:$E$303,"MTM P&L") -> 0 | O8: =SUMIFS('P&L Table'!$F$2:$F$303,'P&L Table'!$A$2:$A$303,"August",'P&L Table'!$C$2:$C$303,$A8,'P&L Table'!$E$2:$E$303,"Commissions") -> 0 | P8: =SUMIFS('P&L Table'!$F$2:$F$303,'P&L Table'!$A$2:$A$303,"August",'P&L Table'!$C$2:$C$303,$A8,'P&L Table'!$E$2:$E$303,"Borrow") -> 0 | Q8: =SUMIFS('P&L Table'!$F$2:$F$303,'P&L Table'!$A$2:$A$303,"August",'P&L Table'!$C$2:$C$303,$A8,'P&L Table'!$E$2:$E$303,"Dividends / PIL") -> 0 | R8: =SUMIFS('P&L Table'!$F$2:$F$303,'P&L Table'!$A$2:$A$303,"August",'P&L Table'!$C$2:$C$303,$A8,'P&L Table'!$E$2:$E$303,"Other") -> 0 | S8: =SUM(N8:R8) -> 0 | T8: =SUMIFS('P&L Table'!$F$2:$F$303,'P&L Table'!$A$2:$A$303,"September",'P&L Table'!$C$2:$C$303,$A8,'P&L Table'!$E$2:$E$303,"MTM P&L") -> 0 | U8: =SUMIFS('P&L Table'!$F$2:$F$303,'P&L Table'!$A$2:$A$303,"September",'P&L Table'!$C$2:$C$303,$A8,'P&L Table'!$E$2:$E$303,"Commissions") -> 0 | V8: =SUMIFS('P&L Table'!$F$2:$F$303,'P&L Table'!$A$2:$A$303,"September",'P&L Table'!$C$2:$C$303,$A8,'P&L Table'!$E$2:$E$303,"Borrow") -> 0 | W8: =SUMIFS('P&L Table'!$F$2:$F$303,'P&L Table'!$A$2:$A$303,"September",'P&L Table'!$C$2:$C$303,$A8,'P&L Table'!$E$2:$E$303,"Dividends / PIL") -> 0 | X8: =SUMIFS('P&L Table'!$F$2:$F$303,'P&L Table'!$A$2:$A$303,"September",'P&L Table'!$C$2:$C$303,$A8,'P&L Table'!$E$2:$E$303,"Other") -> 0 | Y8: =SUM(T8:X8) -> 0 | Z8: =SUMIFS('P&L Table'!$F$2:$F$303,'P&L Table'!$A$2:$A$303,"October",'P&L Table'!$C$2:$C$303,$A8,'P&L Table'!$E$2:$E$303,"MTM P&L") -> 231.71 | AA8: =SUMIFS('P&L Table'!$F$2:$F$303,'P&L Table'!$A$2:$A$303,"October",'P&L Table'!$C$2:$C$303,$A8,'P&L Table'!$E$2:$E$303,"Commissions") -> -15.67 | AB8: =SUMIFS('P&L Table'!$F$2:$F$303,'P&L Table'!$A$2:$A$303,"October",'P&L Table'!$C$2:$C$303,$A8,'P&L Table'!$E$2:$E$303,"Borrow") -> -1.85 | AC8: =SUMIFS('P&L Table'!$F$2:$F$303,'P&L Table'!$A$2:$A$303,"October",'P&L Table'!$C$2:$C$303,$A8,'P&L Table'!$E$2:$E$303,"Dividends / PIL") -> 0 | AD8: =SUMIFS('P&L Table'!$F$2:$F$303,'P&L Table'!$A$2:$A$303,"October",'P&L Table'!$C$2:$C$303,$A8,'P&L Table'!$E$2:$E$303,"Other") -> 0 | AE8: =SUM(Z8:AD8) -> 214.19 | AF8: =SUM(B8,H8,N8,T8,Z8) -> 231.71 | AG8: =SUM(C8,I8,O8,U8,AA8) -> -15.67 | AH8: =SUM(D8,J8,P8,V8,AB8) -> -1.85 | AI8: =SUM(E8,K8,Q8,W8,AC8) -> 0 | AJ8: =SUM(F8,L8,R8,X8,AD8) -> 0 | AK8: =SUM(G8,M8,S8,Y8,AE8) -> 214.19
A9: CMF / VTEC | B9: =SUMIFS('P&L Table'!$F$2:$F$303,'P&L Table'!$A$2:$A$303,"June",'P&L Table'!$C$2:$C$303,$A9,'P&L Table'!$E$2:$E$303,"MTM P&L") -> 0 | C9: =SUMIFS('P&L Table'!$F$2:$F$303,'P&L Table'!$A$2:$A$303,"June",'P&L Table'!$C$2:$C$303,$A9,'P&L Table'!$E$2:$E$303,"Commissions") -> 0 | D9: =SUMIFS('P&L Table'!$F$2:$F$303,'P&L Table'!$A$2:$A$303,"June",'P&L Table'!$C$2:$C$303,$A9,'P&L Table'!$E$2:$E$303,"Borrow") -> 0 | E9: =SUMIFS('P&L Table'!$F$2:$F$303,'P&L Table'!$A$2:$A$303,"June",'P&L Table'!$C$2:$C$303,$A9,'P&L Table'!$E$2:$E$303,"Dividends / PIL") -> 0 | F9: =SUMIFS('P&L Table'!$F$2:$F$303,'P&L Table'!$A$2:$A$303,"June",'P&L Table'!$C$2:$C$303,$A9,'P&L Table'!$E$2:$E$303,"Other") -> 0 | G9: =SUM(B9:F9) -> 0 | H9: =SUMIFS('P&L Table'!$F$2:$F$303,'P&L Table'!$A$2:$A$303,"July",'P&L Table'!$C$2:$C$303,$A9,'P&L Table'!$E$2:$E$303,"MTM P&L") -> 0 | I9: =SUMIFS('P&L Table'!$F$2:$F$303,'P&L Table'!$A$2:$A$303,"July",'P&L Table'!$C$2:$C$303,$A9,'P&L Table'!$E$2:$E$303,"Commissions") -> 0 | J9: =SUMIFS('P&L Table'!$F$2:$F$303,'P&L Table'!$A$2:$A$303,"July",'P&L Table'!$C$2:$C$303,$A9,'P&L Table'!$E$2:$E$303,"Borrow") -> 0 | K9: =SUMIFS('P&L Table'!$F$2:$F$303,'P&L Table'!$A$2:$A$303,"July",'P&L Table'!$C$2:$C$303,$A9,'P&L Table'!$E$2:$E$303,"Dividends / PIL") -> 0 | L9: =SUMIFS('P&L Table'!$F$2:$F$303,'P&L Table'!$A$2:$A$303,"July",'P&L Table'!$C$2:$C$303,$A9,'P&L Table'!$E$2:$E$303,"Other") -> 0 | M9: =SUM(H9:L9) -> 0 | N9: =SUMIFS('P&L Table'!$F$2:$F$303,'P&L Table'!$A$2:$A$303,"August",'P&L Table'!$C$2:$C$303,$A9,'P&L Table'!$E$2:$E$303,"MTM P&L") -> 0 | O9: =SUMIFS('P&L Table'!$F$2:$F$303,'P&L Table'!$A$2:$A$303,"August",'P&L Table'!$C$2:$C$303,$A9,'P&L Table'!$E$2:$E$303,"Commissions") -> 0 | P9: =SUMIFS('P&L Table'!$F$2:$F$303,'P&L Table'!$A$2:$A$303,"August",'P&L Table'!$C$2:$C$303,$A9,'P&L Table'!$E$2:$E$303,"Borrow") -> 0 | Q9: =SUMIFS('P&L Table'!$F$2:$F$303,'P&L Table'!$A$2:$A$303,"August",'P&L Table'!$C$2:$C$303,$A9,'P&L Table'!$E$2:$E$303,"Dividends / PIL") -> 0 | R9: =SUMIFS('P&L Table'!$F$2:$F$303,'P&L Table'!$A$2:$A$303,"August",'P&L Table'!$C$2:$C$303,$A9,'P&L Table'!$E$2:$E$303,"Other") -> 0 | S9: =SUM(N9:R9) -> 0 | T9: =SUMIFS('P&L Table'!$F$2:$F$303,'P&L Table'!$A$2:$A$303,"September",'P&L Table'!$C$2:$C$303,$A9,'P&L Table'!$E$2:$E$303,"MTM P&L") -> 171.4 | U9: =SUMIFS('P&L Table'!$F$2:$F$303,'P&L Table'!$A$2:$A$303,"September",'P&L Table'!$C$2:$C$303,$A9,'P&L Table'!$E$2:$E$303,"Commissions") -> -79.64 | V9: =SUMIFS('P&L Table'!$F$2:$F$303,'P&L Table'!$A$2:$A$303,"September",'P&L Table'!$C$2:$C$303,$A9,'P&L Table'!$E$2:$E$303,"Borrow") -> -58.18 | W9: =SUMIFS('P&L Table'!$F$2:$F$303,'P&L Table'!$A$2:$A$303,"September",'P&L Table'!$C$2:$C$303,$A9,'P&L Table'!$E$2:$E$303,"Dividends / PIL") -> 0 | X9: =SUMIFS('P&L Table'!$F$2:$F$303,'P&L Table'!$A$2:$A$303,"September",'P&L Table'!$C$2:$C$303,$A9,'P&L Table'!$E$2:$E$303,"Other") -> 0 | Y9: =SUM(T9:X9) -> 33.58 | Z9: =SUMIFS('P&L Table'!$F$2:$F$303,'P&L Table'!$A$2:$A$303,"October",'P&L Table'!$C$2:$C$303,$A9,'P&L Table'!$E$2:$E$303,"MTM P&L") -> 520.89 | AA9: =SUMIFS('P&L Table'!$F$2:$F$303,'P&L Table'!$A$2:$A$303,"October",'P&L Table'!$C$2:$C$303,$A9,'P&L Table'!$E$2:$E$303,"Commissions") -> -120.98 | AB9: =SUMIFS('P&L Table'!$F$2:$F$303,'P&L Table'!$A$2:$A$303,"October",'P&L Table'!$C$2:$C$303,$A9,'P&L Table'!$E$2:$E$303,"Borrow") -> -247.13 | AC9: =SUMIFS('P&L Table'!$F$2:$F$303,'P&L Table'!$A$2:$A$303,"October",'P&L Table'!$C$2:$C$303,$A9,'P&L Table'!$E$2:$E$303,"Dividends / PIL") -> 0 | AD9: =SUMIFS('P&L Table'!$F$2:$F$303,'P&L Table'!$A$2:$A$303,"October",'P&L Table'!$C$2:$C$303,$A9,'P&L Table'!$E$2:$E$303,"Other") -> 0 | AE9: =SUM(Z9:AD9) -> 152.78 | AF9: =SUM(B9,H9,N9,T9,Z9) -> 692.29 | AG9: =SUM(C9,I9,O9,U9,AA9) -> -200.62 | AH9: =SUM(D9,J9,P9,V9,AB9) -> -305.31 | AI9: =SUM(E9,K9,Q9,W9,AC9) -> 0 | AJ9: =SUM(F9,L9,R9,X9,AD9) -> 0 | AK9: =SUM(G9,M9,S9,Y9,AE9) -> 186.36
A10: IDU / XLU | B10: =SUMIFS('P&L Table'!$F$2:$F$303,'P&L Table'!$A$2:$A$303,"June",'P&L Table'!$C$2:$C$303,$A10,'P&L Table'!$E$2:$E$303,"MTM P&L") -> 0 | C10: =SUMIFS('P&L Table'!$F$2:$F$303,'P&L Table'!$A$2:$A$303,"June",'P&L Table'!$C$2:$C$303,$A10,'P&L Table'!$E$2:$E$303,"Commissions") -> 0 | D10: =SUMIFS('P&L Table'!$F$2:$F$303,'P&L Table'!$A$2:$A$303,"June",'P&L Table'!$C$2:$C$303,$A10,'P&L Table'!$E$2:$E$303,"Borrow") -> 0 | E10: =SUMIFS('P&L Table'!$F$2:$F$303,'P&L Table'!$A$2:$A$303,"June",'P&L Table'!$C$2:$C$303,$A10,'P&L Table'!$E$2:$E$303,"Dividends / PIL") -> 0 | F10: =SUMIFS('P&L Table'!$F$2:$F$303,'P&L Table'!$A$2:$A$303,"June",'P&L Table'!$C$2:$C$303,$A10,'P&L Table'!$E$2:$E$303,"Other") -> 0 | G10: =SUM(B10:F10) -> 0 | H10: =SUMIFS('P&L Table'!$F$2:$F$303,'P&L Table'!$A$2:$A$303,"July",'P&L Table'!$C$2:$C$303,$A10,'P&L Table'!$E$2:$E$303,"MTM P&L") -> 0 | I10: =SUMIFS('P&L Table'!$F$2:$F$303,'P&L Table'!$A$2:$A$303,"July",'P&L Table'!$C$2:$C$303,$A10,'P&L Table'!$E$2:$E$303,"Commissions") -> 0 | J10: =SUMIFS('P&L Table'!$F$2:$F$303,'P&L Table'!$A$2:$A$303,"July",'P&L Table'!$C$2:$C$303,$A10,'P&L Table'!$E$2:$E$303,"Borrow") -> 0 | K10: =SUMIFS('P&L Table'!$F$2:$F$303,'P&L Table'!$A$2:$A$303,"July",'P&L Table'!$C$2:$C$303,$A10,'P&L Table'!$E$2:$E$303,"Dividends / PIL") -> 0 | L10: =SUMIFS('P&L Table'!$F$2:$F$303,'P&L Table'!$A$2:$A$303,"July",'P&L Table'!$C$2:$C$303,$A10,'P&L Table'!$E$2:$E$303,"Other") -> 0 | M10: =SUM(H10:L10) -> 0 | N10: =SUMIFS('P&L Table'!$F$2:$F$303,'P&L Table'!$A$2:$A$303,"August",'P&L Table'!$C$2:$C$303,$A10,'P&L Table'!$E$2:$E$303,"MTM P&L") -> 0 | O10: =SUMIFS('P&L Table'!$F$2:$F$303,'P&L Table'!$A$2:$A$303,"August",'P&L Table'!$C$2:$C$303,$A10,'P&L Table'!$E$2:$E$303,"Commissions") -> 0 | P10: =SUMIFS('P&L Table'!$F$2:$F$303,'P&L Table'!$A$2:$A$303,"August",'P&L Table'!$C$2:$C$303,$A10,'P&L Table'!$E$2:$E$303,"Borrow") -> 0 | Q10: =SUMIFS('P&L Table'!$F$2:$F$303,'P&L Table'!$A$2:$A$303,"August",'P&L Table'!$C$2:$C$303,$A10,'P&L Table'!$E$2:$E$303,"Dividends / PIL") -> 0 | R10: =SUMIFS('P&L Table'!$F$2:$F$303,'P&L Table'!$A$2:$A$303,"August",'P&L Table'!$C$2:$C$303,$A10,'P&L Table'!$E$2:$E$303,"Other") -> 0 | S10: =SUM(N10:R10) -> 0 | T10: =SUMIFS('P&L Table'!$F$2:$F$303,'P&L Table'!$A$2:$A$303,"September",'P&L Table'!$C$2:$C$303,$A10,'P&L Table'!$E$2:$E$303,"MTM P&L") -> -560.18 | U10: =SUMIFS('P&L Table'!$F$2:$F$303,'P&L Table'!$A$2:$A$303,"September",'P&L Table'!$C$2:$C$303,$A10,'P&L Table'!$E$2:$E$303,"Commissions") -> -74.27 | V10: =SUMIFS('P&L Table'!$F$2:$F$303,'P&L Table'!$A$2:$A$303,"September",'P&L Table'!$C$2:$C$303,$A10,'P&L Table'!$E$2:$E$303,"Borrow") -> -198.87 | W10: =SUMIFS('P&L Table'!$F$2:$F$303,'P&L Table'!$A$2:$A$303,"September",'P&L Table'!$C$2:$C$303,$A10,'P&L Table'!$E$2:$E$303,"Dividends / PIL") -> 856.07 | X10: =SUMIFS('P&L Table'!$F$2:$F$303,'P&L Table'!$A$2:$A$303,"September",'P&L Table'!$C$2:$C$303,$A10,'P&L Table'!$E$2:$E$303,"Other") -> 0 | Y10: =SUM(T10:X10) -> 22.75 | Z10: =SUMIFS('P&L Table'!$F$2:$F$303,'P&L Table'!$A$2:$A$303,"October",'P&L Table'!$C$2:$C$303,$A10,'P&L Table'!$E$2:$E$303,"MTM P&L") -> 166.5 | AA10: =SUMIFS('P&L Table'!$F$2:$F$303,'P&L Table'!$A$2:$A$303,"October",'P&L Table'!$C$2:$C$303,$A10,'P&L Table'!$E$2:$E$303,"Commissions") -> -22.22 | AB10: =SUMIFS('P&L Table'!$F$2:$F$303,'P&L Table'!$A$2:$A$303,"October",'P&L Table'!$C$2:$C$303,$A10,'P&L Table'!$E$2:$E$303,"Borrow") -> -22.18 | AC10: =SUMIFS('P&L Table'!$F$2:$F$303,'P&L Table'!$A$2:$A$303,"October",'P&L Table'!$C$2:$C$303,$A10,'P&L Table'!$E$2:$E$303,"Dividends / PIL") -> 0 | AD10: =SUMIFS('P&L Table'!$F$2:$F$303,'P&L Table'!$A$2:$A$303,"October",'P&L Table'!$C$2:$C$303,$A10,'P&L Table'!$E$2:$E$303,"Other") -> 0 | AE10: =SUM(Z10:AD10) -> 122.1 | AF10: =SUM(B10,H10,N10,T10,Z10) -> -393.68 | AG10: =SUM(C10,I10,O10,U10,AA10) -> -96.49 | AH10: =SUM(D10,J10,P10,V10,AB10) -> -221.05 | AI10: =SUM(E10,K10,Q10,W10,AC10) -> 856.07 | AJ10: =SUM(F10,L10,R10,X10,AD10) -> 0 | AK10: =SUM(G10,M10,S10,Y10,AE10) -> 144.85
A11: CWB / ICVT | B11: =SUMIFS('P&L Table'!$F$2:$F$303,'P&L Table'!$A$2:$A$303,"June",'P&L Table'!$C$2:$C$303,$A11,'P&L Table'!$E$2:$E$303,"MTM P&L") -> 0 | C11: =SUMIFS('P&L Table'!$F$2:$F$303,'P&L Table'!$A$2:$A$303,"June",'P&L Table'!$C$2:$C$303,$A11,'P&L Table'!$E$2:$E$303,"Commissions") -> 0 | D11: =SUMIFS('P&L Table'!$F$2:$F$303,'P&L Table'!$A$2:$A$303,"June",'P&L Table'!$C$2:$C$303,$A11,'P&L Table'!$E$2:$E$303,"Borrow") -> 0 | E11: =SUMIFS('P&L Table'!$F$2:$F$303,'P&L Table'!$A$2:$A$303,"June",'P&L Table'!$C$2:$C$303,$A11,'P&L Table'!$E$2:$E$303,"Dividends / PIL") -> 0 | F11: =SUMIFS('P&L Table'!$F$2:$F$303,'P&L Table'!$A$2:$A$303,"June",'P&L Table'!$C$2:$C$303,$A11,'P&L Table'!$E$2:$E$303,"Other") -> 0 | G11: =SUM(B11:F11) -> 0 | H11: =SUMIFS('P&L Table'!$F$2:$F$303,'P&L Table'!$A$2:$A$303,"July",'P&L Table'!$C$2:$C$303,$A11,'P&L Table'!$E$2:$E$303,"MTM P&L") -> -196.2 | I11: =SUMIFS('P&L Table'!$F$2:$F$303,'P&L Table'!$A$2:$A$303,"July",'P&L Table'!$C$2:$C$303,$A11,'P&L Table'!$E$2:$E$303,"Commissions") -> -56.57 | J11: =SUMIFS('P&L Table'!$F$2:$F$303,'P&L Table'!$A$2:$A$303,"July",'P&L Table'!$C$2:$C$303,$A11,'P&L Table'!$E$2:$E$303,"Borrow") -> -31.96 | K11: =SUMIFS('P&L Table'!$F$2:$F$303,'P&L Table'!$A$2:$A$303,"July",'P&L Table'!$C$2:$C$303,$A11,'P&L Table'!$E$2:$E$303,"Dividends / PIL") -> 0 | L11: =SUMIFS('P&L Table'!$F$2:$F$303,'P&L Table'!$A$2:$A$303,"July",'P&L Table'!$C$2:$C$303,$A11,'P&L Table'!$E$2:$E$303,"Other") -> 0 | M11: =SUM(H11:L11) -> -284.73 | N11: =SUMIFS('P&L Table'!$F$2:$F$303,'P&L Table'!$A$2:$A$303,"August",'P&L Table'!$C$2:$C$303,$A11,'P&L Table'!$E$2:$E$303,"MTM P&L") -> 881.22 | O11: =SUMIFS('P&L Table'!$F$2:$F$303,'P&L Table'!$A$2:$A$303,"August",'P&L Table'!$C$2:$C$303,$A11,'P&L Table'!$E$2:$E$303,"Commissions") -> -28.47 | P11: =SUMIFS('P&L Table'!$F$2:$F$303,'P&L Table'!$A$2:$A$303,"August",'P&L Table'!$C$2:$C$303,$A11,'P&L Table'!$E$2:$E$303,"Borrow") -> -112.45 | Q11: =SUMIFS('P&L Table'!$F$2:$F$303,'P&L Table'!$A$2:$A$303,"August",'P&L Table'!$C$2:$C$303,$A11,'P&L Table'!$E$2:$E$303,"Dividends / PIL") -> -153.02 | R11: =SUMIFS('P&L Table'!$F$2:$F$303,'P&L Table'!$A$2:$A$303,"August",'P&L Table'!$C$2:$C$303,$A11,'P&L Table'!$E$2:$E$303,"Other") -> 0 | S11: =SUM(N11:R11) -> 587.28 | T11: =SUMIFS('P&L Table'!$F$2:$F$303,'P&L Table'!$A$2:$A$303,"September",'P&L Table'!$C$2:$C$303,$A11,'P&L Table'!$E$2:$E$303,"MTM P&L") -> 0 | U11: =SUMIFS('P&L Table'!$F$2:$F$303,'P&L Table'!$A$2:$A$303,"September",'P&L Table'!$C$2:$C$303,$A11,'P&L Table'!$E$2:$E$303,"Commissions") -> 0 | V11: =SUMIFS('P&L Table'!$F$2:$F$303,'P&L Table'!$A$2:$A$303,"September",'P&L Table'!$C$2:$C$303,$A11,'P&L Table'!$E$2:$E$303,"Borrow") -> 0 | W11: =SUMIFS('P&L Table'!$F$2:$F$303,'P&L Table'!$A$2:$A$303,"September",'P&L Table'!$C$2:$C$303,$A11,'P&L Table'!$E$2:$E$303,"Dividends / PIL") -> 0 | X11: =SUMIFS('P&L Table'!$F$2:$F$303,'P&L Table'!$A$2:$A$303,"September",'P&L Table'!$C$2:$C$303,$A11,'P&L Table'!$E$2:$E$303,"Other") -> 0 | Y11: =SUM(T11:X11) -> 0 | Z11: =SUMIFS('P&L Table'!$F$2:$F$303,'P&L Table'!$A$2:$A$303,"October",'P&L Table'!$C$2:$C$303,$A11,'P&L Table'!$E$2:$E$303,"MTM P&L") -> -179.53 | AA11: =SUMIFS('P&L Table'!$F$2:$F$303,'P&L Table'!$A$2:$A$303,"October",'P&L Table'!$C$2:$C$303,$A11,'P&L Table'!$E$2:$E$303,"Commissions") -> -5.16 | AB11: =SUMIFS('P&L Table'!$F$2:$F$303,'P&L Table'!$A$2:$A$303,"October",'P&L Table'!$C$2:$C$303,$A11,'P&L Table'!$E$2:$E$303,"Borrow") -> -7.05 | AC11: =SUMIFS('P&L Table'!$F$2:$F$303,'P&L Table'!$A$2:$A$303,"October",'P&L Table'!$C$2:$C$303,$A11,'P&L Table'!$E$2:$E$303,"Dividends / PIL") -> 0 | AD11: =SUMIFS('P&L Table'!$F$2:$F$303,'P&L Table'!$A$2:$A$303,"October",'P&L Table'!$C$2:$C$303,$A11,'P&L Table'!$E$2:$E$303,"Other") -> 0 | AE11: =SUM(Z11:AD11) -> -191.74 | AF11: =SUM(B11,H11,N11,T11,Z11) -> 505.49 | AG11: =SUM(C11,I11,O11,U11,AA11) -> -90.2 | AH11: =SUM(D11,J11,P11,V11,AB11) -> -151.46 | AI11: =SUM(E11,K11,Q11,W11,AC11) -> -153.02 | AJ11: =SUM(F11,L11,R11,X11,AD11) -> 0 | AK11: =SUM(G11,M11,S11,Y11,AE11) -> 110.81
A12: EMB / VWOB | B12: =SUMIFS('P&L Table'!$F$2:$F$303,'P&L Table'!$A$2:$A$303,"June",'P&L Table'!$C$2:$C$303,$A12,'P&L Table'!$E$2:$E$303,"MTM P&L") -> 0 | C12: =SUMIFS('P&L Table'!$F$2:$F$303,'P&L Table'!$A$2:$A$303,"June",'P&L Table'!$C$2:$C$303,$A12,'P&L Table'!$E$2:$E$303,"Commissions") -> 0 | D12: =SUMIFS('P&L Table'!$F$2:$F$303,'P&L Table'!$A$2:$A$303,"June",'P&L Table'!$C$2:$C$303,$A12,'P&L Table'!$E$2:$E$303,"Borrow") -> 0 | E12: =SUMIFS('P&L Table'!$F$2:$F$303,'P&L Table'!$A$2:$A$303,"June",'P&L Table'!$C$2:$C$303,$A12,'P&L Table'!$E$2:$E$303,"Dividends / PIL") -> 0 | F12: =SUMIFS('P&L Table'!$F$2:$F$303,'P&L Table'!$A$2:$A$303,"June",'P&L Table'!$C$2:$C$303,$A12,'P&L Table'!$E$2:$E$303,"Other") -> 0 | G12: =SUM(B12:F12) -> 0 | H12: =SUMIFS('P&L Table'!$F$2:$F$303,'P&L Table'!$A$2:$A$303,"July",'P&L Table'!$C$2:$C$303,$A12,'P&L Table'!$E$2:$E$303,"MTM P&L") -> 90.2 | I12: =SUMIFS('P&L Table'!$F$2:$F$303,'P&L Table'!$A$2:$A$303,"July",'P&L Table'!$C$2:$C$303,$A12,'P&L Table'!$E$2:$E$303,"Commissions") -> -29.99 | J12: =SUMIFS('P&L Table'!$F$2:$F$303,'P&L Table'!$A$2:$A$303,"July",'P&L Table'!$C$2:$C$303,$A12,'P&L Table'!$E$2:$E$303,"Borrow") -> -9.22 | K12: =SUMIFS('P&L Table'!$F$2:$F$303,'P&L Table'!$A$2:$A$303,"July",'P&L Table'!$C$2:$C$303,$A12,'P&L Table'!$E$2:$E$303,"Dividends / PIL") -> 0 | L12: =SUMIFS('P&L Table'!$F$2:$F$303,'P&L Table'!$A$2:$A$303,"July",'P&L Table'!$C$2:$C$303,$A12,'P&L Table'!$E$2:$E$303,"Other") -> 0 | M12: =SUM(H12:L12) -> 50.99 | N12: =SUMIFS('P&L Table'!$F$2:$F$303,'P&L Table'!$A$2:$A$303,"August",'P&L Table'!$C$2:$C$303,$A12,'P&L Table'!$E$2:$E$303,"MTM P&L") -> 0 | O12: =SUMIFS('P&L Table'!$F$2:$F$303,'P&L Table'!$A$2:$A$303,"August",'P&L Table'!$C$2:$C$303,$A12,'P&L Table'!$E$2:$E$303,"Commissions") -> 0 | P12: =SUMIFS('P&L Table'!$F$2:$F$303,'P&L Table'!$A$2:$A$303,"August",'P&L Table'!$C$2:$C$303,$A12,'P&L Table'!$E$2:$E$303,"Borrow") -> -6.5 | Q12: =SUMIFS('P&L Table'!$F$2:$F$303,'P&L Table'!$A$2:$A$303,"August",'P&L Table'!$C$2:$C$303,$A12,'P&L Table'!$E$2:$E$303,"Dividends / PIL") -> 0 | R12: =SUMIFS('P&L Table'!$F$2:$F$303,'P&L Table'!$A$2:$A$303,"August",'P&L Table'!$C$2:$C$303,$A12,'P&L Table'!$E$2:$E$303,"Other") -> 0 | S12: =SUM(N12:R12) -> -6.5 | T12: =SUMIFS('P&L Table'!$F$2:$F$303,'P&L Table'!$A$2:$A$303,"September",'P&L Table'!$C$2:$C$303,$A12,'P&L Table'!$E$2:$E$303,"MTM P&L") -> 0 | U12: =SUMIFS('P&L Table'!$F$2:$F$303,'P&L Table'!$A$2:$A$303,"September",'P&L Table'!$C$2:$C$303,$A12,'P&L Table'!$E$2:$E$303,"Commissions") -> 0 | V12: =SUMIFS('P&L Table'!$F$2:$F$303,'P&L Table'!$A$2:$A$303,"September",'P&L Table'!$C$2:$C$303,$A12,'P&L Table'!$E$2:$E$303,"Borrow") -> 0 | W12: =SUMIFS('P&L Table'!$F$2:$F$303,'P&L Table'!$A$2:$A$303,"September",'P&L Table'!$C$2:$C$303,$A12,'P&L Table'!$E$2:$E$303,"Dividends / PIL") -> 0 | X12: =SUMIFS('P&L Table'!$F$2:$F$303,'P&L Table'!$A$2:$A$303,"September",'P&L Table'!$C$2:$C$303,$A12,'P&L Table'!$E$2:$E$303,"Other") -> 0 | Y12: =SUM(T12:X12) -> 0 | Z12: =SUMIFS('P&L Table'!$F$2:$F$303,'P&L Table'!$A$2:$A$303,"October",'P&L Table'!$C$2:$C$303,$A12,'P&L Table'!$E$2:$E$303,"MTM P&L") -> 0 | AA12: =SUMIFS('P&L Table'!$F$2:$F$303,'P&L Table'!$A$2:$A$303,"October",'P&L Table'!$C$2:$C$303,$A12,'P&L Table'!$E$2:$E$303,"Commissions") -> 0 | AB12: =SUMIFS('P&L Table'!$F$2:$F$303,'P&L Table'!$A$2:$A$303,"October",'P&L Table'!$C$2:$C$303,$A12,'P&L Table'!$E$2:$E$303,"Borrow") -> 0 | AC12: =SUMIFS('P&L Table'!$F$2:$F$303,'P&L Table'!$A$2:$A$303,"October",'P&L Table'!$C$2:$C$303,$A12,'P&L Table'!$E$2:$E$303,"Dividends / PIL") -> 0 | AD12: =SUMIFS('P&L Table'!$F$2:$F$303,'P&L Table'!$A$2:$A$303,"October",'P&L Table'!$C$2:$C$303,$A12,'P&L Table'!$E$2:$E$303,"Other") -> 0 | AE12: =SUM(Z12:AD12) -> 0 | AF12: =SUM(B12,H12,N12,T12,Z12) -> 90.2 | AG12: =SUM(C12,I12,O12,U12,AA12) -> -29.99 | AH12: =SUM(D12,J12,P12,V12,AB12) -> -15.72 | AI12: =SUM(E12,K12,Q12,W12,AC12) -> 0 | AJ12: =SUM(F12,L12,R12,X12,AD12) -> 0 | AK12: =SUM(G12,M12,S12,Y12,AE12) -> 44.49
A13: EMLC / LEMB | B13: =SUMIFS('P&L Table'!$F$2:$F$303,'P&L Table'!$A$2:$A$303,"June",'P&L Table'!$C$2:$C$303,$A13,'P&L Table'!$E$2:$E$303,"MTM P&L") -> 0 | C13: =SUMIFS('P&L Table'!$F$2:$F$303,'P&L Table'!$A$2:$A$303,"June",'P&L Table'!$C$2:$C$303,$A13,'P&L Table'!$E$2:$E$303,"Commissions") -> 0 | D13: =SUMIFS('P&L Table'!$F$2:$F$303,'P&L Table'!$A$2:$A$303,"June",'P&L Table'!$C$2:$C$303,$A13,'P&L Table'!$E$2:$E$303,"Borrow") -> 0 | E13: =SUMIFS('P&L Table'!$F$2:$F$303,'P&L Table'!$A$2:$A$303,"June",'P&L Table'!$C$2:$C$303,$A13,'P&L Table'!$E$2:$E$303,"Dividends / PIL") -> 0 | F13: =SUMIFS('P&L Table'!$F$2:$F$303,'P&L Table'!$A$2:$A$303,"June",'P&L Table'!$C$2:$C$303,$A13,'P&L Table'!$E$2:$E$303,"Other") -> 0 | G13: =SUM(B13:F13) -> 0 | H13: =SUMIFS('P&L Table'!$F$2:$F$303,'P&L Table'!$A$2:$A$303,"July",'P&L Table'!$C$2:$C$303,$A13,'P&L Table'!$E$2:$E$303,"MTM P&L") -> 0 | I13: =SUMIFS('P&L Table'!$F$2:$F$303,'P&L Table'!$A$2:$A$303,"July",'P&L Table'!$C$2:$C$303,$A13,'P&L Table'!$E$2:$E$303,"Commissions") -> 0 | J13: =SUMIFS('P&L Table'!$F$2:$F$303,'P&L Table'!$A$2:$A$303,"July",'P&L Table'!$C$2:$C$303,$A13,'P&L Table'!$E$2:$E$303,"Borrow") -> 0 | K13: =SUMIFS('P&L Table'!$F$2:$F$303,'P&L Table'!$A$2:$A$303,"July",'P&L Table'!$C$2:$C$303,$A13,'P&L Table'!$E$2:$E$303,"Dividends / PIL") -> 0 | L13: =SUMIFS('P&L Table'!$F$2:$F$303,'P&L Table'!$A$2:$A$303,"July",'P&L Table'!$C$2:$C$303,$A13,'P&L Table'!$E$2:$E$303,"Other") -> 0 | M13: =SUM(H13:L13) -> 0 | N13: =SUMIFS('P&L Table'!$F$2:$F$303,'P&L Table'!$A$2:$A$303,"August",'P&L Table'!$C$2:$C$303,$A13,'P&L Table'!$E$2:$E$303,"MTM P&L") -> 0 | O13: =SUMIFS('P&L Table'!$F$2:$F$303,'P&L Table'!$A$2:$A$303,"August",'P&L Table'!$C$2:$C$303,$A13,'P&L Table'!$E$2:$E$303,"Commissions") -> 0 | P13: =SUMIFS('P&L Table'!$F$2:$F$303,'P&L Table'!$A$2:$A$303,"August",'P&L Table'!$C$2:$C$303,$A13,'P&L Table'!$E$2:$E$303,"Borrow") -> 0 | Q13: =SUMIFS('P&L Table'!$F$2:$F$303,'P&L Table'!$A$2:$A$303,"August",'P&L Table'!$C$2:$C$303,$A13,'P&L Table'!$E$2:$E$303,"Dividends / PIL") -> 0 | R13: =SUMIFS('P&L Table'!$F$2:$F$303,'P&L Table'!$A$2:$A$303,"August",'P&L Table'!$C$2:$C$303,$A13,'P&L Table'!$E$2:$E$303,"Other") -> 0 | S13: =SUM(N13:R13) -> 0 | T13: =SUMIFS('P&L Table'!$F$2:$F$303,'P&L Table'!$A$2:$A$303,"September",'P&L Table'!$C$2:$C$303,$A13,'P&L Table'!$E$2:$E$303,"MTM P&L") -> 0 | U13: =SUMIFS('P&L Table'!$F$2:$F$303,'P&L Table'!$A$2:$A$303,"September",'P&L Table'!$C$2:$C$303,$A13,'P&L Table'!$E$2:$E$303,"Commissions") -> 0 | V13: =SUMIFS('P&L Table'!$F$2:$F$303,'P&L Table'!$A$2:$A$303,"September",'P&L Table'!$C$2:$C$303,$A13,'P&L Table'!$E$2:$E$303,"Borrow") -> 0 | W13: =SUMIFS('P&L Table'!$F$2:$F$303,'P&L Table'!$A$2:$A$303,"September",'P&L Table'!$C$2:$C$303,$A13,'P&L Table'!$E$2:$E$303,"Dividends / PIL") -> 0 | X13: =SUMIFS('P&L Table'!$F$2:$F$303,'P&L Table'!$A$2:$A$303,"September",'P&L Table'!$C$2:$C$303,$A13,'P&L Table'!$E$2:$E$303,"Other") -> 0 | Y13: =SUM(T13:X13) -> 0 | Z13: =SUMIFS('P&L Table'!$F$2:$F$303,'P&L Table'!$A$2:$A$303,"October",'P&L Table'!$C$2:$C$303,$A13,'P&L Table'!$E$2:$E$303,"MTM P&L") -> 52.45 | AA13: =SUMIFS('P&L Table'!$F$2:$F$303,'P&L Table'!$A$2:$A$303,"October",'P&L Table'!$C$2:$C$303,$A13,'P&L Table'!$E$2:$E$303,"Commissions") -> -16.46 | AB13: =SUMIFS('P&L Table'!$F$2:$F$303,'P&L Table'!$A$2:$A$303,"October",'P&L Table'!$C$2:$C$303,$A13,'P&L Table'!$E$2:$E$303,"Borrow") -> -0.46 | AC13: =SUMIFS('P&L Table'!$F$2:$F$303,'P&L Table'!$A$2:$A$303,"October",'P&L Table'!$C$2:$C$303,$A13,'P&L Table'!$E$2:$E$303,"Dividends / PIL") -> 0 | AD13: =SUMIFS('P&L Table'!$F$2:$F$303,'P&L Table'!$A$2:$A$303,"October",'P&L Table'!$C$2:$C$303,$A13,'P&L Table'!$E$2:$E$303,"Other") -> 0 | AE13: =SUM(Z13:AD13) -> 35.53 | AF13: =SUM(B13,H13,N13,T13,Z13) -> 52.45 | AG13: =SUM(C13,I13,O13,U13,AA13) -> -16.46 | AH13: =SUM(D13,J13,P13,V13,AB13) -> -0.46 | AI13: =SUM(E13,K13,Q13,W13,AC13) -> 0 | AJ13: =SUM(F13,L13,R13,X13,AD13) -> 0 | AK13: =SUM(G13,M13,S13,Y13,AE13) -> 35.53
A14: LBTYA / LBTYK | B14: =SUMIFS('P&L Table'!$F$2:$F$303,'P&L Table'!$A$2:$A$303,"June",'P&L Table'!$C$2:$C$303,$A14,'P&L Table'!$E$2:$E$303,"MTM P&L") -> 0 | C14: =SUMIFS('P&L Table'!$F$2:$F$303,'P&L Table'!$A$2:$A$303,"June",'P&L Table'!$C$2:$C$303,$A14,'P&L Table'!$E$2:$E$303,"Commissions") -> 0 | D14: =SUMIFS('P&L Table'!$F$2:$F$303,'P&L Table'!$A$2:$A$303,"June",'P&L Table'!$C$2:$C$303,$A14,'P&L Table'!$E$2:$E$303,"Borrow") -> 0 | E14: =SUMIFS('P&L Table'!$F$2:$F$303,'P&L Table'!$A$2:$A$303,"June",'P&L Table'!$C$2:$C$303,$A14,'P&L Table'!$E$2:$E$303,"Dividends / PIL") -> 0 | F14: =SUMIFS('P&L Table'!$F$2:$F$303,'P&L Table'!$A$2:$A$303,"June",'P&L Table'!$C$2:$C$303,$A14,'P&L Table'!$E$2:$E$303,"Other") -> 0 | G14: =SUM(B14:F14) -> 0 | H14: =SUMIFS('P&L Table'!$F$2:$F$303,'P&L Table'!$A$2:$A$303,"July",'P&L Table'!$C$2:$C$303,$A14,'P&L Table'!$E$2:$E$303,"MTM P&L") -> 0 | I14: =SUMIFS('P&L Table'!$F$2:$F$303,'P&L Table'!$A$2:$A$303,"July",'P&L Table'!$C$2:$C$303,$A14,'P&L Table'!$E$2:$E$303,"Commissions") -> 0 | J14: =SUMIFS('P&L Table'!$F$2:$F$303,'P&L Table'!$A$2:$A$303,"July",'P&L Table'!$C$2:$C$303,$A14,'P&L Table'!$E$2:$E$303,"Borrow") -> 0 | K14: =SUMIFS('P&L Table'!$F$2:$F$303,'P&L Table'!$A$2:$A$303,"July",'P&L Table'!$C$2:$C$303,$A14,'P&L Table'!$E$2:$E$303,"Dividends / PIL") -> 0 | L14: =SUMIFS('P&L Table'!$F$2:$F$303,'P&L Table'!$A$2:$A$303,"July",'P&L Table'!$C$2:$C$303,$A14,'P&L Table'!$E$2:$E$303,"Other") -> 0 | M14: =SUM(H14:L14) -> 0 | N14: =SUMIFS('P&L Table'!$F$2:$F$303,'P&L Table'!$A$2:$A$303,"August",'P&L Table'!$C$2:$C$303,$A14,'P&L Table'!$E$2:$E$303,"MTM P&L") -> 0 | O14: =SUMIFS('P&L Table'!$F$2:$F$303,'P&L Table'!$A$2:$A$303,"August",'P&L Table'!$C$2:$C$303,$A14,'P&L Table'!$E$2:$E$303,"Commissions") -> 0 | P14: =SUMIFS('P&L Table'!$F$2:$F$303,'P&L Table'!$A$2:$A$303,"August",'P&L Table'!$C$2:$C$303,$A14,'P&L Table'!$E$2:$E$303,"Borrow") -> 0 | Q14: =SUMIFS('P&L Table'!$F$2:$F$303,'P&L Table'!$A$2:$A$303,"August",'P&L Table'!$C$2:$C$303,$A14,'P&L Table'!$E$2:$E$303,"Dividends / PIL") -> 0 | R14: =SUMIFS('P&L Table'!$F$2:$F$303,'P&L Table'!$A$2:$A$303,"August",'P&L Table'!$C$2:$C$303,$A14,'P&L Table'!$E$2:$E$303,"Other") -> 0 | S14: =SUM(N14:R14) -> 0 | T14: =SUMIFS('P&L Table'!$F$2:$F$303,'P&L Table'!$A$2:$A$303,"September",'P&L Table'!$C$2:$C$303,$A14,'P&L Table'!$E$2:$E$303,"MTM P&L") -> 0 | U14: =SUMIFS('P&L Table'!$F$2:$F$303,'P&L Table'!$A$2:$A$303,"September",'P&L Table'!$C$2:$C$303,$A14,'P&L Table'!$E$2:$E$303,"Commissions") -> 0 | V14: =SUMIFS('P&L Table'!$F$2:$F$303,'P&L Table'!$A$2:$A$303,"September",'P&L Table'!$C$2:$C$303,$A14,'P&L Table'!$E$2:$E$303,"Borrow") -> 0 | W14: =SUMIFS('P&L Table'!$F$2:$F$303,'P&L Table'!$A$2:$A$303,"September",'P&L Table'!$C$2:$C$303,$A14,'P&L Table'!$E$2:$E$303,"Dividends / PIL") -> 0 | X14: =SUMIFS('P&L Table'!$F$2:$F$303,'P&L Table'!$A$2:$A$303,"September",'P&L Table'!$C$2:$C$303,$A14,'P&L Table'!$E$2:$E$303,"Other") -> 0 | Y14: =SUM(T14:X14) -> 0 | Z14: =SUMIFS('P&L Table'!$F$2:$F$303,'P&L Table'!$A$2:$A$303,"October",'P&L Table'!$C$2:$C$303,$A14,'P&L Table'!$E$2:$E$303,"MTM P&L") -> -11.46 | AA14: =SUMIFS('P&L Table'!$F$2:$F$303,'P&L Table'!$A$2:$A$303,"October",'P&L Table'!$C$2:$C$303,$A14,'P&L Table'!$E$2:$E$303,"Commissions") -> -10.33 | AB14: =SUMIFS('P&L Table'!$F$2:$F$303,'P&L Table'!$A$2:$A$303,"October",'P&L Table'!$C$2:$C$303,$A14,'P&L Table'!$E$2:$E$303,"Borrow") -> -0.12 | AC14: =SUMIFS('P&L Table'!$F$2:$F$303,'P&L Table'!$A$2:$A$303,"October",'P&L Table'!$C$2:$C$303,$A14,'P&L Table'!$E$2:$E$303,"Dividends / PIL") -> 0 | AD14: =SUMIFS('P&L Table'!$F$2:$F$303,'P&L Table'!$A$2:$A$303,"October",'P&L Table'!$C$2:$C$303,$A14,'P&L Table'!$E$2:$E$303,"Other") -> 0 | AE14: =SUM(Z14:AD14) -> -21.91 | AF14: =SUM(B14,H14,N14,T14,Z14) -> -11.46 | AG14: =SUM(C14,I14,O14,U14,AA14) -> -10.33 | AH14: =SUM(D14,J14,P14,V14,AB14) -> -0.12 | AI14: =SUM(E14,K14,Q14,W14,AC14) -> 0 | AJ14: =SUM(F14,L14,R14,X14,AD14) -> 0 | AK14: =SUM(G14,M14,S14,Y14,AE14) -> -21.91
A15: BTCW / IBIT | B15: =SUMIFS('P&L Table'!$F$2:$F$303,'P&L Table'!$A$2:$A$303,"June",'P&L Table'!$C$2:$C$303,$A15,'P&L Table'!$E$2:$E$303,"MTM P&L") -> -62.99 | C15: =SUMIFS('P&L Table'!$F$2:$F$303,'P&L Table'!$A$2:$A$303,"June",'P&L Table'!$C$2:$C$303,$A15,'P&L Table'!$E$2:$E$303,"Commissions") -> -18.12 | D15: =SUMIFS('P&L Table'!$F$2:$F$303,'P&L Table'!$A$2:$A$303,"June",'P&L Table'!$C$2:$C$303,$A15,'P&L Table'!$E$2:$E$303,"Borrow") -> 0 | E15: =SUMIFS('P&L Table'!$F$2:$F$303,'P&L Table'!$A$2:$A$303,"June",'P&L Table'!$C$2:$C$303,$A15,'P&L Table'!$E$2:$E$303,"Dividends / PIL") -> 0 | F15: =SUMIFS('P&L Table'!$F$2:$F$303,'P&L Table'!$A$2:$A$303,"June",'P&L Table'!$C$2:$C$303,$A15,'P&L Table'!$E$2:$E$303,"Other") -> 0 | G15: =SUM(B15:F15) -> -81.11 | H15: =SUMIFS('P&L Table'!$F$2:$F$303,'P&L Table'!$A$2:$A$303,"July",'P&L Table'!$C$2:$C$303,$A15,'P&L Table'!$E$2:$E$303,"MTM P&L") -> 7.2 | I15: =SUMIFS('P&L Table'!$F$2:$F$303,'P&L Table'!$A$2:$A$303,"July",'P&L Table'!$C$2:$C$303,$A15,'P&L Table'!$E$2:$E$303,"Commissions") -> -14.21 | J15: =SUMIFS('P&L Table'!$F$2:$F$303,'P&L Table'!$A$2:$A$303,"July",'P&L Table'!$C$2:$C$303,$A15,'P&L Table'!$E$2:$E$303,"Borrow") -> -1.26 | K15: =SUMIFS('P&L Table'!$F$2:$F$303,'P&L Table'!$A$2:$A$303,"July",'P&L Table'!$C$2:$C$303,$A15,'P&L Table'!$E$2:$E$303,"Dividends / PIL") -> 0 | L15: =SUMIFS('P&L Table'!$F$2:$F$303,'P&L Table'!$A$2:$A$303,"July",'P&L Table'!$C$2:$C$303,$A15,'P&L Table'!$E$2:$E$303,"Other") -> 0 | M15: =SUM(H15:L15) -> -8.27 | N15: =SUMIFS('P&L Table'!$F$2:$F$303,'P&L Table'!$A$2:$A$303,"August",'P&L Table'!$C$2:$C$303,$A15,'P&L Table'!$E$2:$E$303,"MTM P&L") -> 0 | O15: =SUMIFS('P&L Table'!$F$2:$F$303,'P&L Table'!$A$2:$A$303,"August",'P&L Table'!$C$2:$C$303,$A15,'P&L Table'!$E$2:$E$303,"Commissions") -> 0 | P15: =SUMIFS('P&L Table'!$F$2:$F$303,'P&L Table'!$A$2:$A$303,"August",'P&L Table'!$C$2:$C$303,$A15,'P&L Table'!$E$2:$E$303,"Borrow") -> 0 | Q15: =SUMIFS('P&L Table'!$F$2:$F$303,'P&L Table'!$A$2:$A$303,"August",'P&L Table'!$C$2:$C$303,$A15,'P&L Table'!$E$2:$E$303,"Dividends / PIL") -> 0 | R15: =SUMIFS('P&L Table'!$F$2:$F$303,'P&L Table'!$A$2:$A$303,"August",'P&L Table'!$C$2:$C$303,$A15,'P&L Table'!$E$2:$E$303,"Other") -> 0 | S15: =SUM(N15:R15) -> 0 | T15: =SUMIFS('P&L Table'!$F$2:$F$303,'P&L Table'!$A$2:$A$303,"September",'P&L Table'!$C$2:$C$303,$A15,'P&L Table'!$E$2:$E$303,"MTM P&L") -> 0 | U15: =SUMIFS('P&L Table'!$F$2:$F$303,'P&L Table'!$A$2:$A$303,"September",'P&L Table'!$C$2:$C$303,$A15,'P&L Table'!$E$2:$E$303,"Commissions") -> 0 | V15: =SUMIFS('P&L Table'!$F$2:$F$303,'P&L Table'!$A$2:$A$303,"September",'P&L Table'!$C$2:$C$303,$A15,'P&L Table'!$E$2:$E$303,"Borrow") -> 0 | W15: =SUMIFS('P&L Table'!$F$2:$F$303,'P&L Table'!$A$2:$A$303,"September",'P&L Table'!$C$2:$C$303,$A15,'P&L Table'!$E$2:$E$303,"Dividends / PIL") -> 0 | X15: =SUMIFS('P&L Table'!$F$2:$F$303,'P&L Table'!$A$2:$A$303,"September",'P&L Table'!$C$2:$C$303,$A15,'P&L Table'!$E$2:$E$303,"Other") -> 0 | Y15: =SUM(T15:X15) -> 0 | Z15: =SUMIFS('P&L Table'!$F$2:$F$303,'P&L Table'!$A$2:$A$303,"October",'P&L Table'!$C$2:$C$303,$A15,'P&L Table'!$E$2:$E$303,"MTM P&L") -> 0 | AA15: =SUMIFS('P&L Table'!$F$2:$F$303,'P&L Table'!$A$2:$A$303,"October",'P&L Table'!$C$2:$C$303,$A15,'P&L Table'!$E$2:$E$303,"Commissions") -> 0 | AB15: =SUMIFS('P&L Table'!$F$2:$F$303,'P&L Table'!$A$2:$A$303,"October",'P&L Table'!$C$2:$C$303,$A15,'P&L Table'!$E$2:$E$303,"Borrow") -> 0 | AC15: =SUMIFS('P&L Table'!$F$2:$F$303,'P&L Table'!$A$2:$A$303,"October",'P&L Table'!$C$2:$C$303,$A15,'P&L Table'!$E$2:$E$303,"Dividends / PIL") -> 0 | AD15: =SUMIFS('P&L Table'!$F$2:$F$303,'P&L Table'!$A$2:$A$303,"October",'P&L Table'!$C$2:$C$303,$A15,'P&L Table'!$E$2:$E$303,"Other") -> 0 | AE15: =SUM(Z15:AD15) -> 0 | AF15: =SUM(B15,H15,N15,T15,Z15) -> -55.79 | AG15: =SUM(C15,I15,O15,U15,AA15) -> -32.33 | AH15: =SUM(D15,J15,P15,V15,AB15) -> -1.26 | AI15: =SUM(E15,K15,Q15,W15,AC15) -> 0 | AJ15: =SUM(F15,L15,R15,X15,AD15) -> 0 | AK15: =SUM(G15,M15,S15,Y15,AE15) -> -89.38
A16: TLT / VGLT | B16: =SUMIFS('P&L Table'!$F$2:$F$303,'P&L Table'!$A$2:$A$303,"June",'P&L Table'!$C$2:$C$303,$A16,'P&L Table'!$E$2:$E$303,"MTM P&L") -> 0 | C16: =SUMIFS('P&L Table'!$F$2:$F$303,'P&L Table'!$A$2:$A$303,"June",'P&L Table'!$C$2:$C$303,$A16,'P&L Table'!$E$2:$E$303,"Commissions") -> 0 | D16: =SUMIFS('P&L Table'!$F$2:$F$303,'P&L Table'!$A$2:$A$303,"June",'P&L Table'!$C$2:$C$303,$A16,'P&L Table'!$E$2:$E$303,"Borrow") -> 0 | E16: =SUMIFS('P&L Table'!$F$2:$F$303,'P&L Table'!$A$2:$A$303,"June",'P&L Table'!$C$2:$C$303,$A16,'P&L Table'!$E$2:$E$303,"Dividends / PIL") -> 0 | F16: =SUMIFS('P&L Table'!$F$2:$F$303,'P&L Table'!$A$2:$A$303,"June",'P&L Table'!$C$2:$C$303,$A16,'P&L Table'!$E$2:$E$303,"Other") -> 0 | G16: =SUM(B16:F16) -> 0 | H16: =SUMIFS('P&L Table'!$F$2:$F$303,'P&L Table'!$A$2:$A$303,"July",'P&L Table'!$C$2:$C$303,$A16,'P&L Table'!$E$2:$E$303,"MTM P&L") -> -45.96 | I16: =SUMIFS('P&L Table'!$F$2:$F$303,'P&L Table'!$A$2:$A$303,"July",'P&L Table'!$C$2:$C$303,$A16,'P&L Table'!$E$2:$E$303,"Commissions") -> -51.56 | J16: =SUMIFS('P&L Table'!$F$2:$F$303,'P&L Table'!$A$2:$A$303,"July",'P&L Table'!$C$2:$C$303,$A16,'P&L Table'!$E$2:$E$303,"Borrow") -> -16.17 | K16: =SUMIFS('P&L Table'!$F$2:$F$303,'P&L Table'!$A$2:$A$303,"July",'P&L Table'!$C$2:$C$303,$A16,'P&L Table'!$E$2:$E$303,"Dividends / PIL") -> 0 | L16: =SUMIFS('P&L Table'!$F$2:$F$303,'P&L Table'!$A$2:$A$303,"July",'P&L Table'!$C$2:$C$303,$A16,'P&L Table'!$E$2:$E$303,"Other") -> 0 | M16: =SUM(H16:L16) -> -113.69 | N16: =SUMIFS('P&L Table'!$F$2:$F$303,'P&L Table'!$A$2:$A$303,"August",'P&L Table'!$C$2:$C$303,$A16,'P&L Table'!$E$2:$E$303,"MTM P&L") -> -47.82 | O16: =SUMIFS('P&L Table'!$F$2:$F$303,'P&L Table'!$A$2:$A$303,"August",'P&L Table'!$C$2:$C$303,$A16,'P&L Table'!$E$2:$E$303,"Commissions") -> -35.51 | P16: =SUMIFS('P&L Table'!$F$2:$F$303,'P&L Table'!$A$2:$A$303,"August",'P&L Table'!$C$2:$C$303,$A16,'P&L Table'!$E$2:$E$303,"Borrow") -> -104.22 | Q16: =SUMIFS('P&L Table'!$F$2:$F$303,'P&L Table'!$A$2:$A$303,"August",'P&L Table'!$C$2:$C$303,$A16,'P&L Table'!$E$2:$E$303,"Dividends / PIL") -> -9.67 | R16: =SUMIFS('P&L Table'!$F$2:$F$303,'P&L Table'!$A$2:$A$303,"August",'P&L Table'!$C$2:$C$303,$A16,'P&L Table'!$E$2:$E$303,"Other") -> 0 | S16: =SUM(N16:R16) -> -197.22 | T16: =SUMIFS('P&L Table'!$F$2:$F$303,'P&L Table'!$A$2:$A$303,"September",'P&L Table'!$C$2:$C$303,$A16,'P&L Table'!$E$2:$E$303,"MTM P&L") -> 0 | U16: =SUMIFS('P&L Table'!$F$2:$F$303,'P&L Table'!$A$2:$A$303,"September",'P&L Table'!$C$2:$C$303,$A16,'P&L Table'!$E$2:$E$303,"Commissions") -> 0 | V16: =SUMIFS('P&L Table'!$F$2:$F$303,'P&L Table'!$A$2:$A$303,"September",'P&L Table'!$C$2:$C$303,$A16,'P&L Table'!$E$2:$E$303,"Borrow") -> 0 | W16: =SUMIFS('P&L Table'!$F$2:$F$303,'P&L Table'!$A$2:$A$303,"September",'P&L Table'!$C$2:$C$303,$A16,'P&L Table'!$E$2:$E$303,"Dividends / PIL") -> 0 | X16: =SUMIFS('P&L Table'!$F$2:$F$303,'P&L Table'!$A$2:$A$303,"September",'P&L Table'!$C$2:$C$303,$A16,'P&L Table'!$E$2:$E$303,"Other") -> 0 | Y16: =SUM(T16:X16) -> 0 | Z16: =SUMIFS('P&L Table'!$F$2:$F$303,'P&L Table'!$A$2:$A$303,"October",'P&L Table'!$C$2:$C$303,$A16,'P&L Table'!$E$2:$E$303,"MTM P&L") -> 0 | AA16: =SUMIFS('P&L Table'!$F$2:$F$303,'P&L Table'!$A$2:$A$303,"October",'P&L Table'!$C$2:$C$303,$A16,'P&L Table'!$E$2:$E$303,"Commissions") -> 0 | AB16: =SUMIFS('P&L Table'!$F$2:$F$303,'P&L Table'!$A$2:$A$303,"October",'P&L Table'!$C$2:$C$303,$A16,'P&L Table'!$E$2:$E$303,"Borrow") -> 0 | AC16: =SUMIFS('P&L Table'!$F$2:$F$303,'P&L Table'!$A$2:$A$303,"October",'P&L Table'!$C$2:$C$303,$A16,'P&L Table'!$E$2:$E$303,"Dividends / PIL") -> 0 | AD16: =SUMIFS('P&L Table'!$F$2:$F$303,'P&L Table'!$A$2:$A$303,"October",'P&L Table'!$C$2:$C$303,$A16,'P&L Table'!$E$2:$E$303,"Other") -> 0 | AE16: =SUM(Z16:AD16) -> 0 | AF16: =SUM(B16,H16,N16,T16,Z16) -> -93.78 | AG16: =SUM(C16,I16,O16,U16,AA16) -> -87.07 | AH16: =SUM(D16,J16,P16,V16,AB16) -> -120.39 | AI16: =SUM(E16,K16,Q16,W16,AC16) -> -9.67 | AJ16: =SUM(F16,L16,R16,X16,AD16) -> 0 | AK16: =SUM(G16,M16,S16,Y16,AE16) -> -310.91
... A27: IYF / XLF | B27: =SUMIFS('P&L Table'!$F$2:$F$303,'P&L Table'!$A$2:$A$303,"June",'P&L Table'!$C$2:$C$303,$A27,'P&L Table'!$E$2:$E$303,"MTM P&L") -> 0 | C27: =SUMIFS('P&L Table'!$F$2:$F$303,'P&L Table'!$A$2:$A$303,"June",'P&L Table'!$C$2:$C$303,$A27,'P&L Table'!$E$2:$E$303,"Commissions") -> 0 | D27: =SUMIFS('P&L Table'!$F$2:$F$303,'P&L Table'!$A$2:$A$303,"June",'P&L Table'!$C$2:$C$303,$A27,'P&L Table'!$E$2:$E$303,"Borrow") -> 0 | E27: =SUMIFS('P&L Table'!$F$2:$F$303,'P&L Table'!$A$2:$A$303,"June",'P&L Table'!$C$2:$C$303,$A27,'P&L Table'!$E$2:$E$303,"Dividends / PIL") -> 0 | F27: =SUMIFS('P&L Table'!$F$2:$F$303,'P&L Table'!$A$2:$A$303,"June",'P&L Table'!$C$2:$C$303,$A27,'P&L Table'!$E$2:$E$303,"Other") -> 0 | G27: =SUM(B27:F27) -> 0 | H27: =SUMIFS('P&L Table'!$F$2:$F$303,'P&L Table'!$A$2:$A$303,"July",'P&L Table'!$C$2:$C$303,$A27,'P&L Table'!$E$2:$E$303,"MTM P&L") -> 0 | I27: =SUMIFS('P&L Table'!$F$2:$F$303,'P&L Table'!$A$2:$A$303,"July",'P&L Table'!$C$2:$C$303,$A27,'P&L Table'!$E$2:$E$303,"Commissions") -> 0 | J27: =SUMIFS('P&L Table'!$F$2:$F$303,'P&L Table'!$A$2:$A$303,"July",'P&L Table'!$C$2:$C$303,$A27,'P&L Table'!$E$2:$E$303,"Borrow") -> 0 | K27: =SUMIFS('P&L Table'!$F$2:$F$303,'P&L Table'!$A$2:$A$303,"July",'P&L Table'!$C$2:$C$303,$A27,'P&L Table'!$E$2:$E$303,"Dividends / PIL") -> 0 | L27: =SUMIFS('P&L Table'!$F$2:$F$303,'P&L Table'!$A$2:$A$303,"July",'P&L Table'!$C$2:$C$303,$A27,'P&L Table'!$E$2:$E$303,"Other") -> 0 | M27: =SUM(H27:L27) -> 0 | N27: =SUMIFS('P&L Table'!$F$2:$F$303,'P&L Table'!$A$2:$A$303,"August",'P&L Table'!$C$2:$C$303,$A27,'P&L Table'!$E$2:$E$303,"MTM P&L") -> 0 | O27: =SUMIFS('P&L Table'!$F$2:$F$303,'P&L Table'!$A$2:$A$303,"August",'P&L Table'!$C$2:$C$303,$A27,'P&L Table'!$E$2:$E$303,"Commissions") -> 0 | P27: =SUMIFS('P&L Table'!$F$2:$F$303,'P&L Table'!$A$2:$A$303,"August",'P&L Table'!$C$2:$C$303,$A27,'P&L Table'!$E$2:$E$303,"Borrow") -> 0 | Q27: =SUMIFS('P&L Table'!$F$2:$F$303,'P&L Table'!$A$2:$A$303,"August",'P&L Table'!$C$2:$C$303,$A27,'P&L Table'!$E$2:$E$303,"Dividends / PIL") -> 0 | R27: =SUMIFS('P&L Table'!$F$2:$F$303,'P&L Table'!$A$2:$A$303,"August",'P&L Table'!$C$2:$C$303,$A27,'P&L Table'!$E$2:$E$303,"Other") -> 0 | S27: =SUM(N27:R27) -> 0 | T27: =SUMIFS('P&L Table'!$F$2:$F$303,'P&L Table'!$A$2:$A$303,"September",'P&L Table'!$C$2:$C$303,$A27,'P&L Table'!$E$2:$E$303,"MTM P&L") -> 475.3 | U27: =SUMIFS('P&L Table'!$F$2:$F$303,'P&L Table'!$A$2:$A$303,"September",'P&L Table'!$C$2:$C$303,$A27,'P&L Table'!$E$2:$E$303,"Commissions") -> -79.73 | V27: =SUMIFS('P&L Table'!$F$2:$F$303,'P&L Table'!$A$2:$A$303,"September",'P&L Table'!$C$2:$C$303,$A27,'P&L Table'!$E$2:$E$303,"Borrow") -> -9.05 | W27: =SUMIFS('P&L Table'!$F$2:$F$303,'P&L Table'!$A$2:$A$303,"September",'P&L Table'!$C$2:$C$303,$A27,'P&L Table'!$E$2:$E$303,"Dividends / PIL") -> 0 | X27: =SUMIFS('P&L Table'!$F$2:$F$303,'P&L Table'!$A$2:$A$303,"September",'P&L Table'!$C$2:$C$303,$A27,'P&L Table'!$E$2:$E$303,"Other") -> 0 | Y27: =SUM(T27:X27) -> 386.52 | Z27: =SUMIFS('P&L Table'!$F$2:$F$303,'P&L Table'!$A$2:$A$303,"October",'P&L Table'!$C$2:$C$303,$A27,'P&L Table'!$E$2:$E$303,"MTM P&L") -> -5420.47 | AA27: =SUMIFS('P&L Table'!$F$2:$F$303,'P&L Table'!$A$2:$A$303,"October",'P&L Table'!$C$2:$C$303,$A27,'P&L Table'!$E$2:$E$303,"Commissions") -> -11.67 | AB27: =SUMIFS('P&L Table'!$F$2:$F$303,'P&L Table'!$A$2:$A$303,"October",'P&L Table'!$C$2:$C$303,$A27,'P&L Table'!$E$2:$E$303,"Borrow") -> -83.51 | AC27: =SUMIFS('P&L Table'!$F$2:$F$303,'P&L Table'!$A$2:$A$303,"October",'P&L Table'!$C$2:$C$303,$A27,'P&L Table'!$E$2:$E$303,"Dividends / PIL") -> 0 | AD27: =SUMIFS('P&L Table'!$F$2:$F$303,'P&L Table'!$A$2:$A$303,"October",'P&L Table'!$C$2:$C$303,$A27,'P&L Table'!$E$2:$E$303,"Other") -> 0 | AE27: =SUM(Z27:AD27) -> -5515.65 | AF27: =SUM(B27,H27,N27,T27,Z27) -> -4945.17 | AG27: =SUM(C27,I27,O27,U27,AA27) -> -91.4 | AH27: =SUM(D27,J27,P27,V27,AB27) -> -92.56 | AI27: =SUM(E27,K27,Q27,W27,AC27) -> 0 | AJ27: =SUM(F27,L27,R27,X27,AD27) -> 0 | AK27: =SUM(G27,M27,S27,Y27,AE27) -> -5129.13
A28: Equities subtotal | B28: =SUM(B5:B27) -> -62.99 | C28: =SUM(C5:C27) -> -18.12 | D28: =SUM(D5:D27) -> 0 | E28: =SUM(E5:E27) -> 0 | F28: =SUM(F5:F27) -> 0 | G28: =SUM(G5:G27) -> -81.11 | H28: =SUM(H5:H27) -> -3551.35 | I28: =SUM(I5:I27) -> -455.67 | ... AK28: =SUM(AK5:AK27) -> -2917.45
A29: FUTURES
A30: BTC futures | B30: =SUMIFS('P&L Table'!$F$2:$F$303,'P&L Table'!$A$2:$A$303,"June",'P&L Table'!$C$2:$C$303,$A30,'P&L Table'!$E$2:$E$303,"MTM P&L") -> 10378 | C30: =SUMIFS('P&L Table'!$F$2:$F$303,'P&L Table'!$A$2:$A$303,"June",'P&L Table'!$C$2:$C$303,$A30,'P&L Table'!$E$2:$E$303,"Commissions") -> -1982.2 | D30: =SUMIFS('P&L Table'!$F$2:$F$303,'P&L Table'!$A$2:$A$303,"June",'P&L Table'!$C$2:$C$303,$A30,'P&L Table'!$E$2:$E$303,"Borrow") -> 0 | E30: =SUMIFS('P&L Table'!$F$2:$F$303,'P&L Table'!$A$2:$A$303,"June",'P&L Table'!$C$2:$C$303,$A30,'P&L Table'!$E$2:$E$303,"Dividends / PIL") -> 0 | F30: =SUMIFS('P&L Table'!$F$2:$F$303,'P&L Table'!$A$2:$A$303,"June",'P&L Table'!$C$2:$C$303,$A30,'P&L Table'!$E$2:$E$303,"Other") -> 0 | G30: =SUM(B30:F30) -> 8395.8 | H30: =SUMIFS('P&L Table'!$F$2:$F$303,'P&L Table'!$A$2:$A$303,"July",'P&L Table'!$C$2:$C$303,$A30,'P&L Table'!$E$2:$E$303,"MTM P&L") -> 1180 | I30: =SUMIFS('P&L Table'!$F$2:$F$303,'P&L Table'!$A$2:$A$303,"July",'P&L Table'!$C$2:$C$303,$A30,'P&L Table'!$E$2:$E$303,"Commissions") -> -600.52 | J30: =SUMIFS('P&L Table'!$F$2:$F$303,'P&L Table'!$A$2:$A$303,"July",'P&L Table'!$C$2:$C$303,$A30,'P&L Table'!$E$2:$E$303,"Borrow") -> 0 | K30: =SUMIFS('P&L Table'!$F$2:$F$303,'P&L Table'!$A$2:$A$303,"July",'P&L Table'!$C$2:$C$303,$A30,'P&L Table'!$E$2:$E$303,"Dividends / PIL") -> 0 | L30: =SUMIFS('P&L Table'!$F$2:$F$303,'P&L Table'!$A$2:$A$303,"July",'P&L Table'!$C$2:$C$303,$A30,'P&L Table'!$E$2:$E$303,"Other") -> 0 | M30: =SUM(H30:L30) -> 579.48 | N30: =SUMIFS('P&L Table'!$F$2:$F$303,'P&L Table'!$A$2:$A$303,"August",'P&L Table'!$C$2:$C$303,$A30,'P&L Table'!$E$2:$E$303,"MTM P&L") -> 1275 | O30: =SUMIFS('P&L Table'!$F$2:$F$303,'P&L Table'!$A$2:$A$303,"August",'P&L Table'!$C$2:$C$303,$A30,'P&L Table'!$E$2:$E$303,"Commissions") -> -250.2 | P30: =SUMIFS('P&L Table'!$F$2:$F$303,'P&L Table'!$A$2:$A$303,"August",'P&L Table'!$C$2:$C$303,$A30,'P&L Table'!$E$2:$E$303,"Borrow") -> 0 | Q30: =SUMIFS('P&L Table'!$F$2:$F$303,'P&L Table'!$A$2:$A$303,"August",'P&L Table'!$C$2:$C$303,$A30,'P&L Table'!$E$2:$E$303,"Dividends / PIL") -> 0 | R30: =SUMIFS('P&L Table'!$F$2:$F$303,'P&L Table'!$A$2:$A$303,"August",'P&L Table'!$C$2:$C$303,$A30,'P&L Table'!$E$2:$E$303,"Other") -> 0 | S30: =SUM(N30:R30) -> 1024.8 | T30: =SUMIFS('P&L Table'!$F$2:$F$303,'P&L Table'!$A$2:$A$303,"September",'P&L Table'!$C$2:$C$303,$A30,'P&L Table'!$E$2:$E$303,"MTM P&L") -> 890 | U30: =SUMIFS('P&L Table'!$F$2:$F$303,'P&L Table'!$A$2:$A$303,"September",'P&L Table'!$C$2:$C$303,$A30,'P&L Table'!$E$2:$E$303,"Commissions") -> -475.38 | V30: =SUMIFS('P&L Table'!$F$2:$F$303,'P&L Table'!$A$2:$A$303,"September",'P&L Table'!$C$2:$C$303,$A30,'P&L Table'!$E$2:$E$303,"Borrow") -> 0 | W30: =SUMIFS('P&L Table'!$F$2:$F$303,'P&L Table'!$A$2:$A$303,"September",'P&L Table'!$C$2:$C$303,$A30,'P&L Table'!$E$2:$E$303,"Dividends / PIL") -> 0 | X30: =SUMIFS('P&L Table'!$F$2:$F$303,'P&L Table'!$A$2:$A$303,"September",'P&L Table'!$C$2:$C$303,$A30,'P&L Table'!$E$2:$E$303,"Other") -> 0 | Y30: =SUM(T30:X30) -> 414.62 | Z30: =SUMIFS('P&L Table'!$F$2:$F$303,'P&L Table'!$A$2:$A$303,"October",'P&L Table'!$C$2:$C$303,$A30,'P&L Table'!$E$2:$E$303,"MTM P&L") -> 760 | AA30: =SUMIFS('P&L Table'!$F$2:$F$303,'P&L Table'!$A$2:$A$303,"October",'P&L Table'!$C$2:$C$303,$A30,'P&L Table'!$E$2:$E$303,"Commissions") -> -238.68 | AB30: =SUMIFS('P&L Table'!$F$2:$F$303,'P&L Table'!$A$2:$A$303,"October",'P&L Table'!$C$2:$C$303,$A30,'P&L Table'!$E$2:$E$303,"Borrow") -> 0 | AC30: =SUMIFS('P&L Table'!$F$2:$F$303,'P&L Table'!$A$2:$A$303,"October",'P&L Table'!$C$2:$C$303,$A30,'P&L Table'!$E$2:$E$303,"Dividends / PIL") -> 0 | AD30: =SUMIFS('P&L Table'!$F$2:$F$303,'P&L Table'!$A$2:$A$303,"October",'P&L Table'!$C$2:$C$303,$A30,'P&L Table'!$E$2:$E$303,"Other") -> 0 | AE30: =SUM(Z30:AD30) -> 521.32 | AF30: =SUM(B30,H30,N30,T30,Z30) -> 14483 | AG30: =SUM(C30,I30,O30,U30,AA30) -> -3546.98 | AH30: =SUM(D30,J30,P30,V30,AB30) -> 0 | AI30: =SUM(E30,K30,Q30,W30,AC30) -> 0 | AJ30: =SUM(F30,L30,R30,X30,AD30) -> 0 | AK30: =SUM(G30,M30,S30,Y30,AE30) -> 10936.02
